Workbook
Name Matériel: CACHE!$A$2:$A$1001
Name Frais_Artistiques: CACHE!$D$2:$D$1001
Name Prestation_Tech: CACHE!$E$2:$E$1001
Name Frais_Fixes: CACHE!$B$2:$B$1001
Name Vente_Materiel: CACHE!$H$2:$H$1001
Name Frais_Techniques: CACHE!$C$2:$C$1001

Sheet Dashboard
A1: TABLEAU DE BORD -- TRÉSORERIE DEJA VU
A2: Données calculées automatiquement à partir des journaux entrées, sorties et prévisions
B4: Solde Actuel (réel) | D4: Solde Projeté (réel + prev) | F4: Total Entrées Réelles | H4: Total Sorties Réelles | J4: Entrées Prévisionnelles | L4: Sorties Prévisionnelles
B5: {=INDEX(Tresorerie!$D40:$O40,MATCH(MONTH(TODAY()),{1;2;3;4;5;6;7;8;9;10;11;12},0))} -> 1945.68 | D5: {=INDEX(Tresorerie!$D82:$O82,MATCH(MONTH(TODAY()),{1;2;3;4;5;6;7;8;9;10;11;12},0))} -> -1839.5 | F5: =Tresorerie!P37 -> 7765.13 | H5: =Tresorerie!P25 -> 7549.83 | J5: =Tresorerie!P74 -> 6152.8 | L5: =Tresorerie!P62 -> 20358.92
A8: ▶ SYNTHÈSE MENSUELLE
B9: Janvier | C9: Fevrier | D9: Mars | E9: Avril | F9: Mai | G9: Juin | H9: Juillet | I9: Aout | J9: Septembre | K9: Octobre | L9: Novembre | M9: Décembre | N9: TOTAL
A10: DÉPENSES RÉELLES | B10: =Tresorerie!D25 -> 3693.82 | C10: =Tresorerie!E25 -> 1270.44 | D10: =Tresorerie!F25 -> 1416.39 | E10: =Tresorerie!G25 -> 1472.04 | F10: =Tresorerie!H25 -> 468.99 | G10: =Tresorerie!I25 -> 0 | H10: =Tresorerie!J25 -> 0 | I10: =Tresorerie!K25 -> 0 | ... N10: =Tresorerie!P25 -> 7549.83
A11: ENTRÉES RÉELLES | B11: =Tresorerie!D37 -> 2197.08 | C11: =Tresorerie!E37 -> 2530.07 | D11: =Tresorerie!F37 -> 1179.84 | E11: =Tresorerie!G37 -> 1780.4 | F11: =Tresorerie!H37 -> 906.13 | G11: =Tresorerie!I37 -> 0 | H11: =Tresorerie!J37 -> 0 | I11: =Tresorerie!K37 -> 0 | ... N11: =Tresorerie!P37 -> 7765.13
A12: RÉSULTAT NET RÉEL | B12: =Tresorerie!D39 -> -1496.74 | C12: =Tresorerie!E39 -> 1259.63 | D12: =Tresorerie!F39 -> -236.55 | E12: =Tresorerie!G39 -> 308.36 | F12: =Tresorerie!H39 -> 437.14 | G12: =Tresorerie!I39 -> 0 | H12: =Tresorerie!J39 -> 0 | I12: =Tresorerie!K39 -> 0 | ... N12: =Tresorerie!P39 -> 215.3
A13: SOLDE RÉEL CUMULÉ | B13: =Tresorerie!D40 -> 177.1 | C13: =Tresorerie!E40 -> 1436.73 | D13: =Tresorerie!F40 -> 1200.18 | E13: =Tresorerie!G40 -> 1508.54 | F13: =Tresorerie!H40 -> 1945.68 | G13: =Tresorerie!I40 -> 1945.68 | H13: =Tresorerie!J40 -> 1945.68 | I13: =Tresorerie!K40 -> 1945.68 | ... N13: =Tresorerie!P40 -> 1945.68
A14: TOTAL DÉPENSES PRÉV | B14: =Tresorerie!D62 -> 0 | C14: =Tresorerie!E62 -> 0 | D14: =Tresorerie!F62 -> 0 | E14: =Tresorerie!G62 -> 0 | F14: =Tresorerie!H62 -> 1697.99 | G14: =Tresorerie!I62 -> 2412.99 | H14: =Tresorerie!J62 -> 242.99 | I14: =Tresorerie!K62 -> 2542.99 | ... N14: =Tresorerie!P62 -> 20358.92
A15: TOTAL ENTRÉES PRÉV | B15: =Tresorerie!D74 -> 0 | C15: =Tresorerie!E74 -> 0 | D15: =Tresorerie!F74 -> 0 | E15: =Tresorerie!G74 -> 0 | F15: =Tresorerie!H74 -> 0 | G15: =Tresorerie!I74 -> 325.8 | H15: =Tresorerie!J74 -> 1500 | I15: =Tresorerie!K74 -> 1327 | ... N15: =Tresorerie!P74 -> 6152.8
A16: SOLDE PROJETÉ CUMULÉ | B16: =Tresorerie!D82 -> 177.1 | C16: =Tresorerie!E82 -> 1436.73 | D16: =Tresorerie!F82 -> 1200.18 | E16: =Tresorerie!G82 -> 1508.54 | F16: =Tresorerie!H82 -> 247.69 | G16: =Tresorerie!I82 -> -1839.5 | H16: =Tresorerie!J82 -> -582.49 | I16: =Tresorerie!K82 -> -1798.48 | ... N16: =Tresorerie!P82 -> -12260.44
A17: ALERTE SOLVABILITÉ | B17: =IF(B16<0,"⚠️ DÉFICIT",IF(B16<500,"⚡ FAIBLE","✅ OK")) -> ⚡ FAIBLE | C17: =IF(C16<0,"⚠️ DÉFICIT",IF(C16<500,"⚡ FAIBLE","✅ OK")) -> ✅ OK | D17: =IF(D16<0,"⚠️ DÉFICIT",IF(D16<500,"⚡ FAIBLE","✅ OK")) -> ✅ OK | E17: =IF(E16<0,"⚠️ DÉFICIT",IF(E16<500,"⚡ FAIBLE","✅ OK")) -> ✅ OK | F17: =IF(F16<0,"⚠️ DÉFICIT",IF(F16<500,"⚡ FAIBLE","✅ OK")) -> ⚡ FAIBLE | G17: =IF(G16<0,"⚠️ DÉFICIT",IF(G16<500,"⚡ FAIBLE","✅ OK")) -> ⚠️ DÉFICIT | H17: =IF(H16<0,"⚠️ DÉFICIT",IF(H16<500,"⚡ FAIBLE","✅ OK")) -> ⚠️ DÉFICIT | I17: =IF(I16<0,"⚠️ DÉFICIT",IF(I16<500,"⚡ FAIBLE","✅ OK")) -> ⚠️ DÉFICIT | ... N17: =IF(N16<0,"⚠️ DÉFICIT",IF(N16<500,"⚡ FAIBLE","✅ OK")) -> ⚠️ DÉFICIT
A19: ▶ ALERTE DÉCOUVERT PAR MOIS (solde journalier réel)
B20: Jan | C20: Fév | D20: Mar | E20: Avr | F20: Mai | G20: Juin | H20: Juil | I20: Aoû | J20: Sep | K20: Oct | L20: Nov | M20: Déc | N20: Bilan
A21: Risque découvert intra-mois | B21: =Tresorerie!D85 -> ✅ OK | C21: =Tresorerie!E85 -> ✅ OK | D21: =Tresorerie!F85 -> ✅ OK | E21: =Tresorerie!G85 -> ✅ OK | F21: =Tresorerie!H85 -> ✅ OK | G21: =Tresorerie!I85 -> ⛔ DÉCOUVERT | H21: =Tresorerie!J85 -> ⛔ DÉCOUVERT | I21: =Tresorerie!K85 -> ⛔ DÉCOUVERT | ... M21: =Tresorerie!O85 -> ⛔ DÉCOUVERT | N21: =COUNTIF(B21:M21,"⛔ DÉCOUVERT")&" mois à risque" -> 7 mois à risque

Sheet Entrées
A1: Date | B1: Dénomination | C1: Type | D1: Spécification | E1: Facture | F1: Effectué par | G1: Montant TTC | H1: Notes
A2: 46037 | B2: Acompte Soirée Supaero | C2: Prestation_Tech | D2: Location de matériel | F2: AE Supaero | G2: 2197.08
A3: 46056 | B3: Solde Soirée Supaero + Facture additionelle | C3: Prestation_Tech | D3: Location de matériel | F3: AE Supaero | G3: 2387.08
A4: 46064 | B4: Location Matos AAW | C4: Prestation_Tech | D4: Location de matériel | F4: AAW | G4: 95
A5: 46070 | B5: Remboursement Emmetteur/recepteur HDMI Amazon | C5: Remboursement | D5: Remboursement | F5: Amazon | G5: 47.99
A6: 46086 | B6: Paiement AAW | C6: Prestation_Tech | D6: Location de matériel | F6: AAW | G6: 314.84
A7: 46094 | B7: Presta AFTER WINTER | C7: Prestation_Tech | D7: Location de matériel | F7: LAFTER | G7: 865
A8: 46116 | B8: Paiement AAW | C8: Prestation_Tech | D8: Location de matériel | F8: AAW | G8: 1000
A9: 46133 | B9: Recette RELEASE | C9: Recettes_Evenement | D9: Recettes Evenement | F9: Shotgun | G9: 780.4
A10: 46163 | B10: Paiement AAW | C10: Prestation_Tech | D10: Location de matériel | F10: AAW | G10: 906.13

Sheet Sorties
A1: Date | B1: Dénomination | C1: Type | D1: Spécification | E1: Facture | F1: Effectué par | G1: Coût TTC | H1: Notes
A2: 46029 | B2: Prozic | C2: Matériel | D2: Achat de matériel | E2: 2026-01-07 Prozic.pdf | F2: Léo Delmas | G2: 10.41
A3: 46031 | B3: Maif | C3: Frais_Fixes | D3: Assurance | E3: 2026-01-09 Maif.pdf | F3: Léo Delmas | G3: 274.92
A4: 46037 | B4: Abo Google One | C4: Frais_Fixes | D4: Google Drive | F4: Léo Delmas | G4: 2.99
A5: 46038 | B5: Prozic | C5: Matériel | D5: Achat de matériel | E5: 2026-01-16 Prozic.pdf | F5: Léo Delmas | G5: 156.85
A6: 46039 | B6: License Pangolin | C6: Matériel | D6: Location de matériel | E6: 2026-01-17 Pangolin.pdf | F6: Léo Delmas | G6: 93.24
A7: 46039 | B7: Frais location license Beyond | C7: Frais_Fixes | D7: Frais Bancaires | E7: 2026-01-17 Frais Qonto.pdf | G7: 1.87
A8: 46041 | B8: Audiotec | C8: Matériel | D8: Location de matériel | E8: 2026-01-19 Audiotec.pdf | G8: 825.24
A9: 46041 | B9: Carrefour | C9: Frais_Techniques | D9: Transport | G9: 19.75
A10: 46044 | B10: Action | C10: Matériel | D10: Achat de matériel | E10: 2026-01-22 Action.HEIC | F10: Léo Delmas | G10: 13.07
A11: 46044 | B11: Audiotec | C11: Matériel | D11: Achat de matériel | E11: 2026-01-22 Audiotec.pdf | F11: th.trinquier@gmail.com | G11: 119
A12: 46045 | B12: NDF Théo Trinquier | C12: Matériel | D12: Achat de matériel | F12: Léo Delmas | G12: 162.6
A13: 46045 | B13: NDF Théo Trinquier | C13: Frais_Techniques | D13: Transport | F13: Léo Delmas | G13: 547.36
A14: 46045 | B14: Prozic | C14: Matériel | D14: Achat de matériel | E14: 2026-01-23 Prozic.pdf | F14: th.trinquier@gmail.com | G14: 24.44
A15: 46046 | B15: Vinci autoroute péage | C15: Frais_Techniques | D15: Transport | F15: th.trinquier@gmail.com | G15: 1.8
A16: 46047 | B16: NDF Théo Trinquier | C16: Matériel | D16: Achat de matériel | F16: Léo Delmas | G16: 1362.28
A17: 46048 | B17: Audiotec | C17: Matériel | D17: Location de matériel | E17: 2026-01-26 Audiotec.pdf | F17: th.trinquier@gmail.com | G17: 78
A18: 46061 | B18: NDF Théo Trinquier | C18: Frais_Techniques | D18: Transport | F18: Léo Delmas | G18: 20.88
A19: 46061 | B19: NDF Léo Delmas | C19: Matériel | D19: Achat de matériel | F19: Léo Delmas | G19: 998.47
A20: 46068 | B20: Thomann | C20: Matériel | D20: Achat de matériel | E20: 2026-02-15 Thomann.pdf | F20: Léo Delmas | G20: 222
A21: 46068 | B21: Abo Google One | C21: Frais_Fixes | D21: Google Drive | F21: Léo Delmas | G21: 2.99
A22: 46078 | B22: Frais | C22: Frais_Techniques | D22: Techniciens | F22: Léo Delmas | G22: 26.1
A23: 46085 | B23: Prozic | C23: Matériel | D23: Achat de matériel | F23: Léo Delmas | G23: 3.5
A24: 46085 | B24: Tissus plus | C24: Matériel | D24: Achat de matériel | F24: Léo Delmas | G24: 1
A25: 46085 | B25: Bricoman | C25: Matériel | D25: Achat de matériel | F25: Léo Delmas | G25: 8.5
A26: 46087 | B26: Audiotec | C26: Matériel | D26: Achat de matériel | F26: th.trinquier@gmail.com | G26: 72.9
A27: 46089 | B27: Acompte DA Momo | C27: Frais_Artistiques | D27: DA/Graphiste | F27: Léo Delmas | G27: 531
A28: 46096 | B28: Abo Google One | C28: Frais_Fixes | D28: Google Drive | F28: Léo Delmas | G28: 2.99
A29: 46115 | B29: Tshirts Baless | C29: Matériel | D29: Achat de matériel | E29: 2026-04-03 Baless.pdf | F29: Léo Delmas | G29: 400
A30: 46120 | B30: Pub insta | C30: Frais_Artistiques | D30: Communication | F30: Léo Delmas | G30: 10
A31: 46120 | B31: Bizay Stickers | C31: Frais_Artistiques | D31: Communication | F31: Léo Delmas | G31: 47.7
A32: 46121 | B32: Bizay Flyers | C32: Frais_Artistiques | D32: Communication | F32: Léo Delmas | G32: 78.25
A33: 46127 | B33: Abo Google One | C33: Frais_Fixes | D33: Google Drive | F33: Léo Delmas | G33: 2.99
A34: 46128 | B34: Pub insta | C34: Frais_Artistiques | D34: Communication | F34: Léo Delmas | G34: 19.9
A35: 46132 | B35: Booking Hora | C35: Frais_Artistiques | D35: Booking DJ | F35: Léo Delmas | G35: 150
A36: 46140 | B36: Tunnel post | C36: Frais_Artistiques | D36: Communication | F36: Léo Delmas | G36: 150
A37: 46140 | B37: Audiotec | C37: Matériel | D37: Location de matériel | F37: Léo Delmas | G37: 265.2
A38: 46140 | B38: Audiotec | C38: Matériel | D38: Achat de matériel | F38: Léo Delmas | G38: 348
A39: 46145 | B39: Le chorus | C39: Frais_Techniques | D39: Salle | F39: Léo Delmas | G39: 466
A40: 46157 | B40: Abo Google One | C40: Frais_Fixes | D40: Google Drive | F40: Léo Delmas | G40: 2.99
...

Sheet Prévisions
A1: 0 | B1: Dénomination | C1: Type | D1: Spécification | E1: Effectué par | F1: E / S | G1: Coût TTC | H1: Lien | I1: Notes
A2: 46154 | B2: NDF Théo chorus | C2: Frais_Artistiques | D2: Booking DJ | E2: Théo Trinquier | F2: Sortie | G2: 75
A3: 46157 | B3: Flight case CDJ3000X | C3: Matériel | D3: Achat de matériel | E3: th.trinquier@gmail.com | F3: Sortie | G3: 480
A4: 46157 | B4: Abo Google One | C4: Frais_Fixes | D4: Google Drive | E4: Léo Delmas | F4: Sortie | G4: 2.99
A5: 46160 | B5: Peinture caissons | C5: Matériel | D5: Achat de matériel | E5: Léo Delmas | F5: Sortie | G5: 440
A6: 46164 | B6: Complement caissons + roulettes | C6: Matériel | D6: Achat de matériel | E6: th.trinquier@gmail.com | F6: Sortie | G6: 700
A7: 46172 | B7: Flight case Grandma | C7: Matériel | D7: Achat de matériel | E7: corentin.lamontagne@safrangroup.com | F7: Sortie | G7: 0 | I7: 400€ Avance par Corentin
A8: 46179 | B8: Trajet caisson | C8: Frais_Techniques | D8: Location de matériel | E8: Léo Delmas | F8: Sortie | G8: 120
A9: 46188 | B9: Abo Google One | C9: Frais_Fixes | D9: Google Drive | E9: Léo Delmas | F9: Sortie | G9: 2.99
A10: 46188 | B10: Local Florian | C10: Frais_Fixes | D10: Local | E10: Léo Delmas | F10: Sortie | G10: 50 | I10: Coût à définir
A11: 46194 | B11: FDM | C11: Matériel | D11: Location de matériel | E11: Léo Delmas | F11: Sortie | G11: 2000
A12: 46194 | B12: Location Libanais FDM | C12: Prestation_Tech | D12: Location de matériel | E12: Léo Delmas | F12: Entrée | G12: 325.8
A13: 46194 | B13: Location audiotec Libanais | C13: Matériel | D13: Location de matériel | E13: Léo Delmas | F13: Sortie | G13: 240
A14: 46207 | B14: After Summer | C14: Prestation_Tech | D14: Location de matériel | E14: Léo Delmas | F14: Entrée | G14: 1500
A15: 46218 | B15: Chariot pout passe-cable | C15: Matériel | D15: Achat de matériel | E15: Corentin Lamontagne | F15: Sortie | G15: 150 | I15: Estimation de coût incertaine (surement moins cher)
A16: 46218 | B16: Abo Google One | C16: Frais_Fixes | D16: Google Drive | E16: Léo Delmas | F16: Sortie | G16: 2.99
A17: 46218 | B17: Local Florian | C17: Frais_Fixes | D17: Local | E17: Léo Delmas | F17: Sortie | G17: 50
A18: 46234 | B18: Local Tao | C18: Frais_Fixes | D18: Local | E18: Léo Delmas | F18: Sortie | G18: 40
A19: 46235 | B19: Presta Laser Flo | C19: Prestation_Tech | D19: Location de matériel | E19: Léo Delmas | F19: Entrée | G19: 1327
A20: 46248 | B20: Remboursement NDF Léo | C20: Matériel | D20: Achat de matériel | E20: Léo Delmas | F20: Sortie | G20: 1400 | I20: 1er pack tubes leds, loca camion, achat matériel divers...
A21: 46248 | B21: Remboursement NDF Coco | C21: Matériel | D21: Achat de matériel | E21: Léo Delmas | F21: Sortie | G21: 500
A22: 46248 | B22: Remboursement NDF Theo | C22: Matériel | D22: Achat de matériel | E22: Léo Delmas | F22: Sortie | G22: 550
A23: 46249 | B23: Abo Google One | C23: Frais_Fixes | D23: Google Drive | E23: Léo Delmas | F23: Sortie | G23: 2.99
A24: 46249 | B24: Local Florian | C24: Frais_Fixes | D24: Local | E24: Léo Delmas | F24: Sortie | G24: 50
A25: 46265 | B25: Local Tao | C25: Frais_Fixes | D25: Local | E25: Léo Delmas | F25: Sortie | G25: 40
A26: 46270 | B26: BBF Acompte | C26: Prestation_Tech | D26: Location de matériel | E26: Léo Delmas | F26: Entrée | G26: 1000
A27: 46279 | B27: Briteq BT Faze 7500 | C27: Matériel | D27: Achat de matériel | E27: Léo Delmas | F27: Sortie | G27: 600 | I27: A discuter + ROI à faire
A28: 46280 | B28: Abo Google One | C28: Frais_Fixes | D28: Google Drive | E28: Léo Delmas | F28: Sortie | G28: 2.99
A29: 46280 | B29: Loyer Local | C29: Frais_Fixes | D29: Local | E29: Léo Delmas | F29: Sortie | G29: 300
A30: 46284 | B30: BBF Solde | C30: Prestation_Tech | D30: Location de matériel | E30: Léo Delmas | F30: Entrée | G30: 2000
A31: 46295 | B31: 4 barres beam | C31: Matériel | D31: Achat de matériel | E31: Léo Delmas | F31: Sortie | G31: 1000 | I31: A discuter + ROI à faire
A32: 46310 | B32: Abo Google One | C32: Frais_Fixes | D32: Google Drive | E32: Léo Delmas | F32: Sortie | G32: 2.99
A33: 46310 | B33: Loyer Local | C33: Frais_Fixes | D33: Local | E33: Léo Delmas | F33: Sortie | G33: 300
A34: 46326 | B34: Flightcase barre beam | C34: Matériel | D34: Achat de matériel | E34: Léo Delmas | F34: Sortie | G34: 400
A35: 46327 | B35: Acompte Gala Supaero | C35: Prestation_Tech | D35: Location de matériel | E35: Léo Delmas | F35: Entrée | G35: 0 | I35: Était estimé à 9000€
A37: 46328 | B37: 24 Tubes leds | C37: Matériel | D37: Achat de matériel | E37: Léo Delmas | F37: Sortie | G37: 1500
A38: 46329 | B38: Ampli top + cables | C38: Matériel | D38: Achat de matériel | E38: th.trinquier@gmail.com | F38: Sortie | G38: 1250 | I38: A discuter + ROI à faire
A39: 46341 | B39: Abo Google One | C39: Frais_Fixes | D39: Google Drive | E39: Léo Delmas | F39: Sortie | G39: 2.99
A40: 46341 | B40: Loyer Local | C40: Frais_Fixes | D40: Local | E40: Léo Delmas | F40: Sortie | G40: 300
A41: 46342 | B41: 3 praticables | C41: Matériel | D41: Achat de matériel | E41: Léo Delmas | F41: Sortie | G41: 800 | I41: Voir reventes Audiotec, ou occaz
...

Sheet Tresorerie
D1: RÉCAPITULATIF DE TRÉSORERIE – VUE MENSUELLE
D2: Année : | E2: 2026 | F2: Solde Init (€) : | G2: 1673.84
A3: POSTE | D3: 46023 | E3: 46054 | F3: 46082 | G3: 46113 | H3: 46143 | I3: 46174 | J3: 46204 | K3: 46235 | L3: 46266 | M3: 46296 | N3: 46327 | O3: 46357 | P3: Total Annuel
A4: ▶ DÉPENSES RÉELLES
A5: Matériel
A6: Achat de matériel | D6: =SUMIFS(Sorties[Coût TTC],Sorties[Spécification], $A6,Sorties[Date], ">="&D$3,Sorties[Date], "<="&EOMONTH(D$3,0)) -> 1848.65 | E6: =SUMIFS(Sorties[Coût TTC],Sorties[Spécification], $A6,Sorties[Date], ">="&E$3,Sorties[Date], "<="&EOMONTH(E$3,0)) -> 1220.47 | F6: =SUMIFS(Sorties[Coût TTC],Sorties[Spécification], $A6,Sorties[Date], ">="&F$3,Sorties[Date], "<="&EOMONTH(F$3,0)) -> 85.9 | G6: =SUMIFS(Sorties[Coût TTC],Sorties[Spécification], $A6,Sorties[Date], ">="&G$3,Sorties[Date], "<="&EOMONTH(G$3,0)) -> 748 | H6: =SUMIFS(Sorties[Coût TTC],Sorties[Spécification], $A6,Sorties[Date], ">="&H$3,Sorties[Date], "<="&EOMONTH(H$3,0)) -> 0 | I6: =SUMIFS(Sorties[Coût TTC],Sorties[Spécification], $A6,Sorties[Date], ">="&I$3,Sorties[Date], "<="&EOMONTH(I$3,0)) -> 0 | J6: =SUMIFS(Sorties[Coût TTC],Sorties[Spécification], $A6,Sorties[Date], ">="&J$3,Sorties[Date], "<="&EOMONTH(J$3,0)) -> 0 | K6: =SUMIFS(Sorties[Coût TTC],Sorties[Spécification], $A6,Sorties[Date], ">="&K$3,Sorties[Date], "<="&EOMONTH(K$3,0)) -> 0 | ... O6: =SUMIFS(Sorties[Coût TTC],Sorties[Spécification], $A6,Sorties[Date], ">="&O$3,Sorties[Date], "<="&EOMONTH(O$3,0)) -> 0 | P6: =SUM(D6:O6) -> 3903.02
A7: Frais Entretien | D7: =SUMIFS(Sorties[Coût TTC],Sorties[Spécification], $A7,Sorties[Date], ">="&D$3,Sorties[Date], "<="&EOMONTH(D$3,0)) -> 0 | E7: =SUMIFS(Sorties[Coût TTC],Sorties[Spécification], $A7,Sorties[Date], ">="&E$3,Sorties[Date], "<="&EOMONTH(E$3,0)) -> 0 | F7: =SUMIFS(Sorties[Coût TTC],Sorties[Spécification], $A7,Sorties[Date], ">="&F$3,Sorties[Date], "<="&EOMONTH(F$3,0)) -> 0 | G7: =SUMIFS(Sorties[Coût TTC],Sorties[Spécification], $A7,Sorties[Date], ">="&G$3,Sorties[Date], "<="&EOMONTH(G$3,0)) -> 0 | H7: =SUMIFS(Sorties[Coût TTC],Sorties[Spécification], $A7,Sorties[Date], ">="&H$3,Sorties[Date], "<="&EOMONTH(H$3,0)) -> 0 | I7: =SUMIFS(Sorties[Coût TTC],Sorties[Spécification], $A7,Sorties[Date], ">="&I$3,Sorties[Date], "<="&EOMONTH(I$3,0)) -> 0 | J7: =SUMIFS(Sorties[Coût TTC],Sorties[Spécification], $A7,Sorties[Date], ">="&J$3,Sorties[Date], "<="&EOMONTH(J$3,0)) -> 0 | K7: =SUMIFS(Sorties[Coût TTC],Sorties[Spécification], $A7,Sorties[Date], ">="&K$3,Sorties[Date], "<="&EOMONTH(K$3,0)) -> 0 | ... O7: =SUMIFS(Sorties[Coût TTC],Sorties[Spécification], $A7,Sorties[Date], ">="&O$3,Sorties[Date], "<="&EOMONTH(O$3,0)) -> 0 | P7: =SUM(D7:O7) -> 0
A8: Location de matériel | D8: =SUMIFS(Sorties[Coût TTC],Sorties[Spécification], $A8,Sorties[Date], ">="&D$3,Sorties[Date], "<="&EOMONTH(D$3,0)) -> 996.48 | E8: =SUMIFS(Sorties[Coût TTC],Sorties[Spécification], $A8,Sorties[Date], ">="&E$3,Sorties[Date], "<="&EOMONTH(E$3,0)) -> 0 | F8: =SUMIFS(Sorties[Coût TTC],Sorties[Spécification], $A8,Sorties[Date], ">="&F$3,Sorties[Date], "<="&EOMONTH(F$3,0)) -> 0 | G8: =SUMIFS(Sorties[Coût TTC],Sorties[Spécification], $A8,Sorties[Date], ">="&G$3,Sorties[Date], "<="&EOMONTH(G$3,0)) -> 265.2 | H8: =SUMIFS(Sorties[Coût TTC],Sorties[Spécification], $A8,Sorties[Date], ">="&H$3,Sorties[Date], "<="&EOMONTH(H$3,0)) -> 0 | I8: =SUMIFS(Sorties[Coût TTC],Sorties[Spécification], $A8,Sorties[Date], ">="&I$3,Sorties[Date], "<="&EOMONTH(I$3,0)) -> 0 | J8: =SUMIFS(Sorties[Coût TTC],Sorties[Spécification], $A8,Sorties[Date], ">="&J$3,Sorties[Date], "<="&EOMONTH(J$3,0)) -> 0 | K8: =SUMIFS(Sorties[Coût TTC],Sorties[Spécification], $A8,Sorties[Date], ">="&K$3,Sorties[Date], "<="&EOMONTH(K$3,0)) -> 0 | ... O8: =SUMIFS(Sorties[Coût TTC],Sorties[Spécification], $A8,Sorties[Date], ">="&O$3,Sorties[Date], "<="&EOMONTH(O$3,0)) -> 0 | P8: =SUM(D8:O8) -> 1261.68
A9: Frais Fixes
A10: Frais IT | D10: =SUMIFS(Sorties[Coût TTC],Sorties[Spécification], $A10,Sorties[Date], ">="&D$3,Sorties[Date], "<="&EOMONTH(D$3,0)) -> 0 | E10: =SUMIFS(Sorties[Coût TTC],Sorties[Spécification], $A10,Sorties[Date], ">="&E$3,Sorties[Date], "<="&EOMONTH(E$3,0)) -> 0 | F10: =SUMIFS(Sorties[Coût TTC],Sorties[Spécification], $A10,Sorties[Date], ">="&F$3,Sorties[Date], "<="&EOMONTH(F$3,0)) -> 0 | G10: =SUMIFS(Sorties[Coût TTC],Sorties[Spécification], $A10,Sorties[Date], ">="&G$3,Sorties[Date], "<="&EOMONTH(G$3,0)) -> 0 | H10: =SUMIFS(Sorties[Coût TTC],Sorties[Spécification], $A10,Sorties[Date], ">="&H$3,Sorties[Date], "<="&EOMONTH(H$3,0)) -> 0 | I10: =SUMIFS(Sorties[Coût TTC],Sorties[Spécification], $A10,Sorties[Date], ">="&I$3,Sorties[Date], "<="&EOMONTH(I$3,0)) -> 0 | J10: =SUMIFS(Sorties[Coût TTC],Sorties[Spécification], $A10,Sorties[Date], ">="&J$3,Sorties[Date], "<="&EOMONTH(J$3,0)) -> 0 | K10: =SUMIFS(Sorties[Coût TTC],Sorties[Spécification], $A10,Sorties[Date], ">="&K$3,Sorties[Date], "<="&EOMONTH(K$3,0)) -> 0 | ... O10: =SUMIFS(Sorties[Coût TTC],Sorties[Spécification], $A10,Sorties[Date], ">="&O$3,Sorties[Date], "<="&EOMONTH(O$3,0)) -> 0 | P10: =SUM(D10:O10) -> 0
A11: Google Drive | D11: =SUMIFS(Sorties[Coût TTC],Sorties[Spécification], $A11,Sorties[Date], ">="&D$3,Sorties[Date], "<="&EOMONTH(D$3,0)) -> 2.99 | E11: =SUMIFS(Sorties[Coût TTC],Sorties[Spécification], $A11,Sorties[Date], ">="&E$3,Sorties[Date], "<="&EOMONTH(E$3,0)) -> 2.99 | F11: =SUMIFS(Sorties[Coût TTC],Sorties[Spécification], $A11,Sorties[Date], ">="&F$3,Sorties[Date], "<="&EOMONTH(F$3,0)) -> 2.99 | G11: =SUMIFS(Sorties[Coût TTC],Sorties[Spécification], $A11,Sorties[Date], ">="&G$3,Sorties[Date], "<="&EOMONTH(G$3,0)) -> 2.99 | H11: =SUMIFS(Sorties[Coût TTC],Sorties[Spécification], $A11,Sorties[Date], ">="&H$3,Sorties[Date], "<="&EOMONTH(H$3,0)) -> 2.99 | I11: =SUMIFS(Sorties[Coût TTC],Sorties[Spécification], $A11,Sorties[Date], ">="&I$3,Sorties[Date], "<="&EOMONTH(I$3,0)) -> 0 | J11: =SUMIFS(Sorties[Coût TTC],Sorties[Spécification], $A11,Sorties[Date], ">="&J$3,Sorties[Date], "<="&EOMONTH(J$3,0)) -> 0 | K11: =SUMIFS(Sorties[Coût TTC],Sorties[Spécification], $A11,Sorties[Date], ">="&K$3,Sorties[Date], "<="&EOMONTH(K$3,0)) -> 0 | ... O11: =SUMIFS(Sorties[Coût TTC],Sorties[Spécification], $A11,Sorties[Date], ">="&O$3,Sorties[Date], "<="&EOMONTH(O$3,0)) -> 0 | P11: =SUM(D11:O11) -> 14.95
A12: Site Internet | D12: =SUMIFS(Sorties[Coût TTC],Sorties[Spécification], $A12,Sorties[Date], ">="&D$3,Sorties[Date], "<="&EOMONTH(D$3,0)) -> 0 | E12: =SUMIFS(Sorties[Coût TTC],Sorties[Spécification], $A12,Sorties[Date], ">="&E$3,Sorties[Date], "<="&EOMONTH(E$3,0)) -> 0 | F12: =SUMIFS(Sorties[Coût TTC],Sorties[Spécification], $A12,Sorties[Date], ">="&F$3,Sorties[Date], "<="&EOMONTH(F$3,0)) -> 0 | G12: =SUMIFS(Sorties[Coût TTC],Sorties[Spécification], $A12,Sorties[Date], ">="&G$3,Sorties[Date], "<="&EOMONTH(G$3,0)) -> 0 | H12: =SUMIFS(Sorties[Coût TTC],Sorties[Spécification], $A12,Sorties[Date], ">="&H$3,Sorties[Date], "<="&EOMONTH(H$3,0)) -> 0 | I12: =SUMIFS(Sorties[Coût TTC],Sorties[Spécification], $A12,Sorties[Date], ">="&I$3,Sorties[Date], "<="&EOMONTH(I$3,0)) -> 0 | J12: =SUMIFS(Sorties[Coût TTC],Sorties[Spécification], $A12,Sorties[Date], ">="&J$3,Sorties[Date], "<="&EOMONTH(J$3,0)) -> 0 | K12: =SUMIFS(Sorties[Coût TTC],Sorties[Spécification], $A12,Sorties[Date], ">="&K$3,Sorties[Date], "<="&EOMONTH(K$3,0)) -> 0 | ... O12: =SUMIFS(Sorties[Coût TTC],Sorties[Spécification], $A12,Sorties[Date], ">="&O$3,Sorties[Date], "<="&EOMONTH(O$3,0)) -> 0 | P12: =SUM(D12:O12) -> 0
A13: Local | D13: =SUMIFS(Sorties[Coût TTC],Sorties[Spécification], $A13,Sorties[Date], ">="&D$3,Sorties[Date], "<="&EOMONTH(D$3,0)) -> 0 | E13: =SUMIFS(Sorties[Coût TTC],Sorties[Spécification], $A13,Sorties[Date], ">="&E$3,Sorties[Date], "<="&EOMONTH(E$3,0)) -> 0 | F13: =SUMIFS(Sorties[Coût TTC],Sorties[Spécification], $A13,Sorties[Date], ">="&F$3,Sorties[Date], "<="&EOMONTH(F$3,0)) -> 0 | G13: =SUMIFS(Sorties[Coût TTC],Sorties[Spécification], $A13,Sorties[Date], ">="&G$3,Sorties[Date], "<="&EOMONTH(G$3,0)) -> 0 | H13: =SUMIFS(Sorties[Coût TTC],Sorties[Spécification], $A13,Sorties[Date], ">="&H$3,Sorties[Date], "<="&EOMONTH(H$3,0)) -> 0 | P13: =SUM(D13:O13) -> 0
A14: Assurance | D14: =SUMIFS(Sorties[Coût TTC],Sorties[Spécification], $A14,Sorties[Date], ">="&D$3,Sorties[Date], "<="&EOMONTH(D$3,0)) -> 274.92 | E14: =SUMIFS(Sorties[Coût TTC],Sorties[Spécification], $A14,Sorties[Date], ">="&E$3,Sorties[Date], "<="&EOMONTH(E$3,0)) -> 0 | F14: =SUMIFS(Sorties[Coût TTC],Sorties[Spécification], $A14,Sorties[Date], ">="&F$3,Sorties[Date], "<="&EOMONTH(F$3,0)) -> 0 | G14: =SUMIFS(Sorties[Coût TTC],Sorties[Spécification], $A14,Sorties[Date], ">="&G$3,Sorties[Date], "<="&EOMONTH(G$3,0)) -> 0 | H14: =SUMIFS(Sorties[Coût TTC],Sorties[Spécification], $A14,Sorties[Date], ">="&H$3,Sorties[Date], "<="&EOMONTH(H$3,0)) -> 0 | I14: =SUMIFS(Sorties[Coût TTC],Sorties[Spécification], $A14,Sorties[Date], ">="&I$3,Sorties[Date], "<="&EOMONTH(I$3,0)) -> 0 | J14: =SUMIFS(Sorties[Coût TTC],Sorties[Spécification], $A14,Sorties[Date], ">="&J$3,Sorties[Date], "<="&EOMONTH(J$3,0)) -> 0 | K14: =SUMIFS(Sorties[Coût TTC],Sorties[Spécification], $A14,Sorties[Date], ">="&K$3,Sorties[Date], "<="&EOMONTH(K$3,0)) -> 0 | ... O14: =SUMIFS(Sorties[Coût TTC],Sorties[Spécification], $A14,Sorties[Date], ">="&O$3,Sorties[Date], "<="&EOMONTH(O$3,0)) -> 0 | P14: =SUM(D14:O14) -> 274.92
A15: Frais Bancaires | D15: =SUMIFS(Sorties[Coût TTC],Sorties[Spécification], $A15,Sorties[Date], ">="&D$3,Sorties[Date], "<="&EOMONTH(D$3,0)) -> 1.87 | E15: =SUMIFS(Sorties[Coût TTC],Sorties[Spécification], $A15,Sorties[Date], ">="&E$3,Sorties[Date], "<="&EOMONTH(E$3,0)) -> 0 | F15: =SUMIFS(Sorties[Coût TTC],Sorties[Spécification], $A15,Sorties[Date], ">="&F$3,Sorties[Date], "<="&EOMONTH(F$3,0)) -> 0 | G15: =SUMIFS(Sorties[Coût TTC],Sorties[Spécification], $A15,Sorties[Date], ">="&G$3,Sorties[Date], "<="&EOMONTH(G$3,0)) -> 0 | H15: =SUMIFS(Sorties[Coût TTC],Sorties[Spécification], $A15,Sorties[Date], ">="&H$3,Sorties[Date], "<="&EOMONTH(H$3,0)) -> 0 | I15: =SUMIFS(Sorties[Coût TTC],Sorties[Spécification], $A15,Sorties[Date], ">="&I$3,Sorties[Date], "<="&EOMONTH(I$3,0)) -> 0 | J15: =SUMIFS(Sorties[Coût TTC],Sorties[Spécification], $A15,Sorties[Date], ">="&J$3,Sorties[Date], "<="&EOMONTH(J$3,0)) -> 0 | K15: =SUMIFS(Sorties[Coût TTC],Sorties[Spécification], $A15,Sorties[Date], ">="&K$3,Sorties[Date], "<="&EOMONTH(K$3,0)) -> 0 | ... O15: =SUMIFS(Sorties[Coût TTC],Sorties[Spécification], $A15,Sorties[Date], ">="&O$3,Sorties[Date], "<="&EOMONTH(O$3,0)) -> 0 | P15: =SUM(D15:O15) -> 1.87
A16: Frais Technique
A17: Techniciens | D17: =SUMIFS(Sorties[Coût TTC],Sorties[Spécification], $A17,Sorties[Date], ">="&D$3,Sorties[Date], "<="&EOMONTH(D$3,0)) -> 0 | E17: =SUMIFS(Sorties[Coût TTC],Sorties[Spécification], $A17,Sorties[Date], ">="&E$3,Sorties[Date], "<="&EOMONTH(E$3,0)) -> 26.1 | F17: =SUMIFS(Sorties[Coût TTC],Sorties[Spécification], $A17,Sorties[Date], ">="&F$3,Sorties[Date], "<="&EOMONTH(F$3,0)) -> 0 | G17: =SUMIFS(Sorties[Coût TTC],Sorties[Spécification], $A17,Sorties[Date], ">="&G$3,Sorties[Date], "<="&EOMONTH(G$3,0)) -> 0 | H17: =SUMIFS(Sorties[Coût TTC],Sorties[Spécification], $A17,Sorties[Date], ">="&H$3,Sorties[Date], "<="&EOMONTH(H$3,0)) -> 0 | I17: =SUMIFS(Sorties[Coût TTC],Sorties[Spécification], $A17,Sorties[Date], ">="&I$3,Sorties[Date], "<="&EOMONTH(I$3,0)) -> 0 | J17: =SUMIFS(Sorties[Coût TTC],Sorties[Spécification], $A17,Sorties[Date], ">="&J$3,Sorties[Date], "<="&EOMONTH(J$3,0)) -> 0 | K17: =SUMIFS(Sorties[Coût TTC],Sorties[Spécification], $A17,Sorties[Date], ">="&K$3,Sorties[Date], "<="&EOMONTH(K$3,0)) -> 0 | ... O17: =SUMIFS(Sorties[Coût TTC],Sorties[Spécification], $A17,Sorties[Date], ">="&O$3,Sorties[Date], "<="&EOMONTH(O$3,0)) -> 0 | P17: =SUM(D17:O17) -> 26.1
A18: Transport | D18: =SUMIFS(Sorties[Coût TTC],Sorties[Spécification], $A18,Sorties[Date], ">="&D$3,Sorties[Date], "<="&EOMONTH(D$3,0)) -> 568.91 | E18: =SUMIFS(Sorties[Coût TTC],Sorties[Spécification], $A18,Sorties[Date], ">="&E$3,Sorties[Date], "<="&EOMONTH(E$3,0)) -> 20.88 | F18: =SUMIFS(Sorties[Coût TTC],Sorties[Spécification], $A18,Sorties[Date], ">="&F$3,Sorties[Date], "<="&EOMONTH(F$3,0)) -> 0 | G18: =SUMIFS(Sorties[Coût TTC],Sorties[Spécification], $A18,Sorties[Date], ">="&G$3,Sorties[Date], "<="&EOMONTH(G$3,0)) -> 0 | H18: =SUMIFS(Sorties[Coût TTC],Sorties[Spécification], $A18,Sorties[Date], ">="&H$3,Sorties[Date], "<="&EOMONTH(H$3,0)) -> 0 | I18: =SUMIFS(Sorties[Coût TTC],Sorties[Spécification], $A18,Sorties[Date], ">="&I$3,Sorties[Date], "<="&EOMONTH(I$3,0)) -> 0 | J18: =SUMIFS(Sorties[Coût TTC],Sorties[Spécification], $A18,Sorties[Date], ">="&J$3,Sorties[Date], "<="&EOMONTH(J$3,0)) -> 0 | K18: =SUMIFS(Sorties[Coût TTC],Sorties[Spécification], $A18,Sorties[Date], ">="&K$3,Sorties[Date], "<="&EOMONTH(K$3,0)) -> 0 | ... O18: =SUMIFS(Sorties[Coût TTC],Sorties[Spécification], $A18,Sorties[Date], ">="&O$3,Sorties[Date], "<="&EOMONTH(O$3,0)) -> 0 | P18: =SUM(D18:O18) -> 589.79
A19: Salle | D19: =SUMIFS(Sorties[Coût TTC],Sorties[Spécification], $A19,Sorties[Date], ">="&D$3,Sorties[Date], "<="&EOMONTH(D$3,0)) -> 0 | E19: =SUMIFS(Sorties[Coût TTC],Sorties[Spécification], $A19,Sorties[Date], ">="&E$3,Sorties[Date], "<="&EOMONTH(E$3,0)) -> 0 | F19: =SUMIFS(Sorties[Coût TTC],Sorties[Spécification], $A19,Sorties[Date], ">="&F$3,Sorties[Date], "<="&EOMONTH(F$3,0)) -> 0 | G19: =SUMIFS(Sorties[Coût TTC],Sorties[Spécification], $A19,Sorties[Date], ">="&G$3,Sorties[Date], "<="&EOMONTH(G$3,0)) -> 0 | H19: =SUMIFS(Sorties[Coût TTC],Sorties[Spécification], $A19,Sorties[Date], ">="&H$3,Sorties[Date], "<="&EOMONTH(H$3,0)) -> 466 | I19: =SUMIFS(Sorties[Coût TTC],Sorties[Spécification], $A19,Sorties[Date], ">="&I$3,Sorties[Date], "<="&EOMONTH(I$3,0)) -> 0 | J19: =SUMIFS(Sorties[Coût TTC],Sorties[Spécification], $A19,Sorties[Date], ">="&J$3,Sorties[Date], "<="&EOMONTH(J$3,0)) -> 0 | K19: =SUMIFS(Sorties[Coût TTC],Sorties[Spécification], $A19,Sorties[Date], ">="&K$3,Sorties[Date], "<="&EOMONTH(K$3,0)) -> 0 | ... O19: =SUMIFS(Sorties[Coût TTC],Sorties[Spécification], $A19,Sorties[Date], ">="&O$3,Sorties[Date], "<="&EOMONTH(O$3,0)) -> 0
A20: Frais Artistiques
A21: Booking DJ | D21: =SUMIFS(Sorties[Coût TTC],Sorties[Spécification], $A21,Sorties[Date], ">="&D$3,Sorties[Date], "<="&EOMONTH(D$3,0)) -> 0 | E21: =SUMIFS(Sorties[Coût TTC],Sorties[Spécification], $A21,Sorties[Date], ">="&E$3,Sorties[Date], "<="&EOMONTH(E$3,0)) -> 0 | F21: =SUMIFS(Sorties[Coût TTC],Sorties[Spécification], $A21,Sorties[Date], ">="&F$3,Sorties[Date], "<="&EOMONTH(F$3,0)) -> 0 | G21: =SUMIFS(Sorties[Coût TTC],Sorties[Spécification], $A21,Sorties[Date], ">="&G$3,Sorties[Date], "<="&EOMONTH(G$3,0)) -> 150 | H21: =SUMIFS(Sorties[Coût TTC],Sorties[Spécification], $A21,Sorties[Date], ">="&H$3,Sorties[Date], "<="&EOMONTH(H$3,0)) -> 0 | I21: =SUMIFS(Sorties[Coût TTC],Sorties[Spécification], $A21,Sorties[Date], ">="&I$3,Sorties[Date], "<="&EOMONTH(I$3,0)) -> 0 | J21: =SUMIFS(Sorties[Coût TTC],Sorties[Spécification], $A21,Sorties[Date], ">="&J$3,Sorties[Date], "<="&EOMONTH(J$3,0)) -> 0 | K21: =SUMIFS(Sorties[Coût TTC],Sorties[Spécification], $A21,Sorties[Date], ">="&K$3,Sorties[Date], "<="&EOMONTH(K$3,0)) -> 0 | ... O21: =SUMIFS(Sorties[Coût TTC],Sorties[Spécification], $A21,Sorties[Date], ">="&O$3,Sorties[Date], "<="&EOMONTH(O$3,0)) -> 0 | P21: =SUM(D21:O21) -> 150
A22: Photographe/Vidéaste | D22: =SUMIFS(Sorties[Coût TTC],Sorties[Spécification], $A22,Sorties[Date], ">="&D$3,Sorties[Date], "<="&EOMONTH(D$3,0)) -> 0 | E22: =SUMIFS(Sorties[Coût TTC],Sorties[Spécification], $A22,Sorties[Date], ">="&E$3,Sorties[Date], "<="&EOMONTH(E$3,0)) -> 0 | F22: =SUMIFS(Sorties[Coût TTC],Sorties[Spécification], $A22,Sorties[Date], ">="&F$3,Sorties[Date], "<="&EOMONTH(F$3,0)) -> 0 | G22: =SUMIFS(Sorties[Coût TTC],Sorties[Spécification], $A22,Sorties[Date], ">="&G$3,Sorties[Date], "<="&EOMONTH(G$3,0)) -> 0 | H22: =SUMIFS(Sorties[Coût TTC],Sorties[Spécification], $A22,Sorties[Date], ">="&H$3,Sorties[Date], "<="&EOMONTH(H$3,0)) -> 0 | I22: =SUMIFS(Sorties[Coût TTC],Sorties[Spécification], $A22,Sorties[Date], ">="&I$3,Sorties[Date], "<="&EOMONTH(I$3,0)) -> 0 | J22: =SUMIFS(Sorties[Coût TTC],Sorties[Spécification], $A22,Sorties[Date], ">="&J$3,Sorties[Date], "<="&EOMONTH(J$3,0)) -> 0 | K22: =SUMIFS(Sorties[Coût TTC],Sorties[Spécification], $A22,Sorties[Date], ">="&K$3,Sorties[Date], "<="&EOMONTH(K$3,0)) -> 0 | ... O22: =SUMIFS(Sorties[Coût TTC],Sorties[Spécification], $A22,Sorties[Date], ">="&O$3,Sorties[Date], "<="&EOMONTH(O$3,0)) -> 0 | P22: =SUM(D22:O22) -> 0
A23: DA/Graphiste | D23: =SUMIFS(Sorties[Coût TTC],Sorties[Spécification], $A23,Sorties[Date], ">="&D$3,Sorties[Date], "<="&EOMONTH(D$3,0)) -> 0 | E23: =SUMIFS(Sorties[Coût TTC],Sorties[Spécification], $A23,Sorties[Date], ">="&E$3,Sorties[Date], "<="&EOMONTH(E$3,0)) -> 0 | F23: =SUMIFS(Sorties[Coût TTC],Sorties[Spécification], $A23,Sorties[Date], ">="&F$3,Sorties[Date], "<="&EOMONTH(F$3,0)) -> 1327.5 | G23: =SUMIFS(Sorties[Coût TTC],Sorties[Spécification], $A23,Sorties[Date], ">="&G$3,Sorties[Date], "<="&EOMONTH(G$3,0)) -> 0 | H23: =SUMIFS(Sorties[Coût TTC],Sorties[Spécification], $A23,Sorties[Date], ">="&H$3,Sorties[Date], "<="&EOMONTH(H$3,0)) -> 0 | I23: =SUMIFS(Sorties[Coût TTC],Sorties[Spécification], $A23,Sorties[Date], ">="&I$3,Sorties[Date], "<="&EOMONTH(I$3,0)) -> 0 | J23: =SUMIFS(Sorties[Coût TTC],Sorties[Spécification], $A23,Sorties[Date], ">="&J$3,Sorties[Date], "<="&EOMONTH(J$3,0)) -> 0 | K23: =SUMIFS(Sorties[Coût TTC],Sorties[Spécification], $A23,Sorties[Date], ">="&K$3,Sorties[Date], "<="&EOMONTH(K$3,0)) -> 0 | ... O23: =SUMIFS(Sorties[Coût TTC],Sorties[Spécification], $A23,Sorties[Date], ">="&O$3,Sorties[Date], "<="&EOMONTH(O$3,0)) -> 0 | P23: =SUM(D23:O23) -> 1327.5
A24: Communication | D24: =SUMIFS(Sorties[Coût TTC],Sorties[Spécification], $A24,Sorties[Date], ">="&D$3,Sorties[Date], "<="&EOMONTH(D$3,0)) -> 0 | E24: =SUMIFS(Sorties[Coût TTC],Sorties[Spécification], $A24,Sorties[Date], ">="&E$3,Sorties[Date], "<="&EOMONTH(E$3,0)) -> 0 | F24: =SUMIFS(Sorties[Coût TTC],Sorties[Spécification], $A24,Sorties[Date], ">="&F$3,Sorties[Date], "<="&EOMONTH(F$3,0)) -> 0 | G24: =SUMIFS(Sorties[Coût TTC],Sorties[Spécification], $A24,Sorties[Date], ">="&G$3,Sorties[Date], "<="&EOMONTH(G$3,0)) -> 305.85 | H24: =SUMIFS(Sorties[Coût TTC],Sorties[Spécification], $A24,Sorties[Date], ">="&H$3,Sorties[Date], "<="&EOMONTH(H$3,0)) -> 0 | I24: =SUMIFS(Sorties[Coût TTC],Sorties[Spécification], $A24,Sorties[Date], ">="&I$3,Sorties[Date], "<="&EOMONTH(I$3,0)) -> 0 | J24: =SUMIFS(Sorties[Coût TTC],Sorties[Spécification], $A24,Sorties[Date], ">="&J$3,Sorties[Date], "<="&EOMONTH(J$3,0)) -> 0 | K24: =SUMIFS(Sorties[Coût TTC],Sorties[Spécification], $A24,Sorties[Date], ">="&K$3,Sorties[Date], "<="&EOMONTH(K$3,0)) -> 0 | ... O24: =SUMIFS(Sorties[Coût TTC],Sorties[Spécification], $A24,Sorties[Date], ">="&O$3,Sorties[Date], "<="&EOMONTH(O$3,0)) -> 0
A25: TOTAL DÉPENSES | D25: =SUM(D5:D24) -> 3693.82 | E25: =SUM(E5:E24) -> 1270.44 | F25: =SUM(F5:F24) -> 1416.39 | G25: =SUM(G5:G24) -> 1472.04 | H25: =SUM(H5:H24) -> 468.99 | I25: =SUM(I5:I24) -> 0 | J25: =SUM(J5:J24) -> 0 | K25: =SUM(K5:K24) -> 0 | ... O25: =SUM(O5:O24) -> 0 | P25: =SUM(P5:P23) -> 7549.83
A27: ▶ ENTRÉES RÉELLES
A28: Prestation Technique
A29: Location de matériel | D29: =SUMIFS('Entrées'!$G:$G, 'Entrées'!$D:$D, $A29, 'Entrées'!$A:$A, ">="&D$3, 'Entrées'!$A:$A, "<="&EOMONTH(D$3,0)) -> 2197.08 | E29: =SUMIFS('Entrées'!$G:$G, 'Entrées'!$D:$D, $A29, 'Entrées'!$A:$A, ">="&E$3, 'Entrées'!$A:$A, "<="&EOMONTH(E$3,0)) -> 2482.08 | F29: =SUMIFS('Entrées'!$G:$G, 'Entrées'!$D:$D, $A29, 'Entrées'!$A:$A, ">="&F$3, 'Entrées'!$A:$A, "<="&EOMONTH(F$3,0)) -> 1179.84 | G29: =SUMIFS('Entrées'!$G:$G, 'Entrées'!$D:$D, $A29, 'Entrées'!$A:$A, ">="&G$3, 'Entrées'!$A:$A, "<="&EOMONTH(G$3,0)) -> 1000 | H29: =SUMIFS('Entrées'!$G:$G, 'Entrées'!$D:$D, $A29, 'Entrées'!$A:$A, ">="&H$3, 'Entrées'!$A:$A, "<="&EOMONTH(H$3,0)) -> 906.13 | I29: =SUMIFS('Entrées'!$G:$G, 'Entrées'!$D:$D, $A29, 'Entrées'!$A:$A, ">="&I$3, 'Entrées'!$A:$A, "<="&EOMONTH(I$3,0)) -> 0 | J29: =SUMIFS('Entrées'!$G:$G, 'Entrées'!$D:$D, $A29, 'Entrées'!$A:$A, ">="&J$3, 'Entrées'!$A:$A, "<="&EOMONTH(J$3,0)) -> 0 | K29: =SUMIFS('Entrées'!$G:$G, 'Entrées'!$D:$D, $A29, 'Entrées'!$A:$A, ">="&K$3, 'Entrées'!$A:$A, "<="&EOMONTH(K$3,0)) -> 0 | ... O29: =SUMIFS('Entrées'!$G:$G, 'Entrées'!$D:$D, $A29, 'Entrées'!$A:$A, ">="&O$3, 'Entrées'!$A:$A, "<="&EOMONTH(O$3,0)) -> 0 | P29: =SUM(B29:O29) -> 7765.13
A30: Techniciens | D30: =SUMIFS('Entrées'!$G:$G, 'Entrées'!$D:$D, $A30, 'Entrées'!$A:$A, ">="&D$3, 'Entrées'!$A:$A, "<="&EOMONTH(D$3,0)) -> 0 | E30: =SUMIFS('Entrées'!$G:$G, 'Entrées'!$D:$D, $A30, 'Entrées'!$A:$A, ">="&E$3, 'Entrées'!$A:$A, "<="&EOMONTH(E$3,0)) -> 0 | F30: =SUMIFS('Entrées'!$G:$G, 'Entrées'!$D:$D, $A30, 'Entrées'!$A:$A, ">="&F$3, 'Entrées'!$A:$A, "<="&EOMONTH(F$3,0)) -> 0 | G30: =SUMIFS('Entrées'!$G:$G, 'Entrées'!$D:$D, $A30, 'Entrées'!$A:$A, ">="&G$3, 'Entrées'!$A:$A, "<="&EOMONTH(G$3,0)) -> 0 | H30: =SUMIFS('Entrées'!$G:$G, 'Entrées'!$D:$D, $A30, 'Entrées'!$A:$A, ">="&H$3, 'Entrées'!$A:$A, "<="&EOMONTH(H$3,0)) -> 0 | I30: =SUMIFS('Entrées'!$G:$G, 'Entrées'!$D:$D, $A30, 'Entrées'!$A:$A, ">="&I$3, 'Entrées'!$A:$A, "<="&EOMONTH(I$3,0)) -> 0 | J30: =SUMIFS('Entrées'!$G:$G, 'Entrées'!$D:$D, $A30, 'Entrées'!$A:$A, ">="&J$3, 'Entrées'!$A:$A, "<="&EOMONTH(J$3,0)) -> 0 | K30: =SUMIFS('Entrées'!$G:$G, 'Entrées'!$D:$D, $A30, 'Entrées'!$A:$A, ">="&K$3, 'Entrées'!$A:$A, "<="&EOMONTH(K$3,0)) -> 0 | ... O30: =SUMIFS('Entrées'!$G:$G, 'Entrées'!$D:$D, $A30, 'Entrées'!$A:$A, ">="&O$3, 'Entrées'!$A:$A, "<="&EOMONTH(O$3,0)) -> 0 | P30: =SUM(B30:O30) -> 0
A31: Vente de matériel
A32: Vente de matériel | D32: =SUMIFS('Entrées'!$G:$G, 'Entrées'!$D:$D, $A32, 'Entrées'!$A:$A, ">="&D$3, 'Entrées'!$A:$A, "<="&EOMONTH(D$3,0)) -> 0 | E32: =SUMIFS('Entrées'!$G:$G, 'Entrées'!$D:$D, $A32, 'Entrées'!$A:$A, ">="&E$3, 'Entrées'!$A:$A, "<="&EOMONTH(E$3,0)) -> 0 | F32: =SUMIFS('Entrées'!$G:$G, 'Entrées'!$D:$D, $A32, 'Entrées'!$A:$A, ">="&F$3, 'Entrées'!$A:$A, "<="&EOMONTH(F$3,0)) -> 0 | G32: =SUMIFS('Entrées'!$G:$G, 'Entrées'!$D:$D, $A32, 'Entrées'!$A:$A, ">="&G$3, 'Entrées'!$A:$A, "<="&EOMONTH(G$3,0)) -> 0 | H32: =SUMIFS('Entrées'!$G:$G, 'Entrées'!$D:$D, $A32, 'Entrées'!$A:$A, ">="&H$3, 'Entrées'!$A:$A, "<="&EOMONTH(H$3,0)) -> 0 | I32: =SUMIFS('Entrées'!$G:$G, 'Entrées'!$D:$D, $A32, 'Entrées'!$A:$A, ">="&I$3, 'Entrées'!$A:$A, "<="&EOMONTH(I$3,0)) -> 0 | J32: =SUMIFS('Entrées'!$G:$G, 'Entrées'!$D:$D, $A32, 'Entrées'!$A:$A, ">="&J$3, 'Entrées'!$A:$A, "<="&EOMONTH(J$3,0)) -> 0 | K32: =SUMIFS('Entrées'!$G:$G, 'Entrées'!$D:$D, $A32, 'Entrées'!$A:$A, ">="&K$3, 'Entrées'!$A:$A, "<="&EOMONTH(K$3,0)) -> 0 | ... O32: =SUMIFS('Entrées'!$G:$G, 'Entrées'!$D:$D, $A32, 'Entrées'!$A:$A, ">="&O$3, 'Entrées'!$A:$A, "<="&EOMONTH(O$3,0)) -> 0 | P32: =SUM(B32:O32) -> 0
A33: Recette Evenement
A34: Recettes Evenement | D34: =SUMIFS('Entrées'!$G:$G, 'Entrées'!$D:$D, $A34, 'Entrées'!$A:$A, ">="&D$3, 'Entrées'!$A:$A, "<="&EOMONTH(D$3,0)) -> 0 | E34: =SUMIFS('Entrées'!$G:$G, 'Entrées'!$D:$D, $A34, 'Entrées'!$A:$A, ">="&E$3, 'Entrées'!$A:$A, "<="&EOMONTH(E$3,0)) -> 0 | F34: =SUMIFS('Entrées'!$G:$G, 'Entrées'!$D:$D, $A34, 'Entrées'!$A:$A, ">="&F$3, 'Entrées'!$A:$A, "<="&EOMONTH(F$3,0)) -> 0 | G34: =SUMIFS('Entrées'!$G:$G, 'Entrées'!$D:$D, $A34, 'Entrées'!$A:$A, ">="&G$3, 'Entrées'!$A:$A, "<="&EOMONTH(G$3,0)) -> 780.4 | H34: =SUMIFS('Entrées'!$G:$G, 'Entrées'!$D:$D, $A34, 'Entrées'!$A:$A, ">="&H$3, 'Entrées'!$A:$A, "<="&EOMONTH(H$3,0)) -> 0 | I34: =SUMIFS('Entrées'!$G:$G, 'Entrées'!$D:$D, $A34, 'Entrées'!$A:$A, ">="&I$3, 'Entrées'!$A:$A, "<="&EOMONTH(I$3,0)) -> 0 | J34: =SUMIFS('Entrées'!$G:$G, 'Entrées'!$D:$D, $A34, 'Entrées'!$A:$A, ">="&J$3, 'Entrées'!$A:$A, "<="&EOMONTH(J$3,0)) -> 0 | K34: =SUMIFS('Entrées'!$G:$G, 'Entrées'!$D:$D, $A34, 'Entrées'!$A:$A, ">="&K$3, 'Entrées'!$A:$A, "<="&EOMONTH(K$3,0)) -> 0 | ... O34: =SUMIFS('Entrées'!$G:$G, 'Entrées'!$D:$D, $A34, 'Entrées'!$A:$A, ">="&O$3, 'Entrées'!$A:$A, "<="&EOMONTH(O$3,0)) -> 0 | P34: =SUM(B34:O34) -> 780.4
A35: Remboursement
A36: Remboursement | D36: =SUMIFS('Entrées'!$G:$G, 'Entrées'!$D:$D, $A36, 'Entrées'!$A:$A, ">="&D$3, 'Entrées'!$A:$A, "<="&EOMONTH(D$3,0)) -> 0 | E36: =SUMIFS('Entrées'!$G:$G, 'Entrées'!$D:$D, $A36, 'Entrées'!$A:$A, ">="&E$3, 'Entrées'!$A:$A, "<="&EOMONTH(E$3,0)) -> 47.99 | F36: =SUMIFS('Entrées'!$G:$G, 'Entrées'!$D:$D, $A36, 'Entrées'!$A:$A, ">="&F$3, 'Entrées'!$A:$A, "<="&EOMONTH(F$3,0)) -> 0 | G36: =SUMIFS('Entrées'!$G:$G, 'Entrées'!$D:$D, $A36, 'Entrées'!$A:$A, ">="&G$3, 'Entrées'!$A:$A, "<="&EOMONTH(G$3,0)) -> 0 | H36: =SUMIFS('Entrées'!$G:$G, 'Entrées'!$D:$D, $A36, 'Entrées'!$A:$A, ">="&H$3, 'Entrées'!$A:$A, "<="&EOMONTH(H$3,0)) -> 0 | I36: =SUMIFS('Entrées'!$G:$G, 'Entrées'!$D:$D, $A36, 'Entrées'!$A:$A, ">="&I$3, 'Entrées'!$A:$A, "<="&EOMONTH(I$3,0)) -> 0 | J36: =SUMIFS('Entrées'!$G:$G, 'Entrées'!$D:$D, $A36, 'Entrées'!$A:$A, ">="&J$3, 'Entrées'!$A:$A, "<="&EOMONTH(J$3,0)) -> 0 | K36: =SUMIFS('Entrées'!$G:$G, 'Entrées'!$D:$D, $A36, 'Entrées'!$A:$A, ">="&K$3, 'Entrées'!$A:$A, "<="&EOMONTH(K$3,0)) -> 0 | ... O36: =SUMIFS('Entrées'!$G:$G, 'Entrées'!$D:$D, $A36, 'Entrées'!$A:$A, ">="&O$3, 'Entrées'!$A:$A, "<="&EOMONTH(O$3,0)) -> 0 | P36: =SUM(B36:O36) -> 47.99
A37: TOTAL ENTRÉES | D37: =SUM(D28:D32) -> 2197.08 | E37: =SUM(E28:E36) -> 2530.07 | F37: =SUM(F28:F36) -> 1179.84 | G37: =SUM(G28:G36) -> 1780.4 | H37: =SUM(H28:H36) -> 906.13 | I37: =SUM(I28:I36) -> 0 | J37: =SUM(J28:J36) -> 0 | K37: =SUM(K28:K36) -> 0 | L37: =SUM(L28:L36) -> 0 | ... O37: =SUM(O28:O36) -> 0 | P37: =SUM(P28:P32) -> 7765.13
A39: RÉSULTAT NET RÉEL | D39: =D37-D25 -> -1496.74 | E39: =E37-E25 -> 1259.63 | F39: =F37-F25 -> -236.55 | G39: =G37-G25 -> 308.36 | H39: =H37-H25 -> 437.14 | I39: =I37-I25 -> 0 | J39: =J37-J25 -> 0 | K39: =K37-K25 -> 0 | ... P39: =P37-P25 -> 215.3
A40: SOLDE RÉEL CUMULÉ | D40: =$G$2+D39 -> 177.1 | E40: =D40+E39 -> 1436.73 | F40: =E40+F39 -> 1200.18 | G40: =F40+G39 -> 1508.54 | H40: =G40+H39 -> 1945.68 | I40: =H40+I39 -> 1945.68 | J40: =I40+J39 -> 1945.68 | K40: =J40+K39 -> 1945.68 | L40: =K40+L39 -> 1945.68 | ... O40: =N40+O39 -> 1945.68 | P40: =O40 -> 1945.68
A42: ▶ PRÉVISIONNEL
A43: ▶ SORTIES PRÉV
...

Sheet Flux Journalier
A1: FLUX JOURNALIER – DÉTECTION DES PASSAGES EN NÉGATIF | J1: 0
A2: Le solde cumulé est recalculé chaque jour à partir des opérations réelles saisies dans les journaux. Les lignes en ROUGE signalent un solde négatif = risque de découvert bancaire.
A3: Seuil d'alerte (€) : | C3: 500 | E3: ← Montant en dessous duquel l'alerte se déclenche
A4: Date | B4: Jour | C4: Entrées réelles (€) | D4: Entrées prévisionnelles (€) | E4: Dépenses réelles (€) | F4: Dépenses prévisionnelles (€) | G4: Flux net du jour (€) | H4: SOLDE CUMULÉ (€) | I4: Statut
A5: =DATE(Tresorerie!$E$2,1,1)+J4 -> 46023 | B5: =TEXT(A5,"DDD") -> jeu. | C5: =SUMPRODUCT((Entrées[Date]=A5)*IF(ISNUMBER(Entrées[Montant TTC]),Entrées[Montant TTC],0)) -> 0 | D5: =SUMPRODUCT((Prévisions[0]=A5)*IF(Prévisions[E / S]="Entrée",IF(ISNUMBER(Prévisions[Coût TTC]),Prévisions[Coût TTC],0),0)) -> 0 | E5: =SUMPRODUCT((Sorties[Date]=A5)*IF(ISNUMBER(Sorties[Coût TTC]),Sorties[Coût TTC],0)) -> 0 | F5: =SUMPRODUCT((Prévisions[0]=A5)*IF(Prévisions[E / S]="Sortie",IF(ISNUMBER(Prévisions[Coût TTC]),Prévisions[Coût TTC],0),0)) -> 0 | G5: =(C5+D5)-(E5+F5) -> 0 | H5: =Tresorerie!$G$2+G5 -> 1673.84 | I5: =IF(H5<0,"⛔ DÉCOUVERT",IF(H5<$C$3,"⚡ Solde faible","✅ OK")) -> ✅ OK | J5: 1
A6: =DATE(Tresorerie!$E$2,1,1)+J5 -> 46024 | B6: =TEXT(A6,"DDD") -> ven. | C6: =SUMPRODUCT((Entrées[Date]=A6)*IF(ISNUMBER(Entrées[Montant TTC]),Entrées[Montant TTC],0)) -> 0 | D6: =SUMPRODUCT((Prévisions[0]=A6)*IF(Prévisions[E / S]="Entrée",IF(ISNUMBER(Prévisions[Coût TTC]),Prévisions[Coût TTC],0),0)) -> 0 | E6: =SUMPRODUCT((Sorties[Date]=A6)*IF(ISNUMBER(Sorties[Coût TTC]),Sorties[Coût TTC],0)) -> 0 | F6: =SUMPRODUCT((Prévisions[0]=A6)*IF(Prévisions[E / S]="Sortie",IF(ISNUMBER(Prévisions[Coût TTC]),Prévisions[Coût TTC],0),0)) -> 0 | G6: =(C6+D6)-(E6+F6) -> 0 | H6: =Tresorerie!$G$2+G6 -> 1673.84 | I6: =IF(H6<0,"⛔ DÉCOUVERT",IF(H6<$C$3,"⚡ Solde faible","✅ OK")) -> ✅ OK | J6: 2
A7: =DATE(Tresorerie!$E$2,1,1)+J6 -> 46025 | B7: =TEXT(A7,"DDD") -> sam. | C7: =SUMPRODUCT((Entrées[Date]=A7)*IF(ISNUMBER(Entrées[Montant TTC]),Entrées[Montant TTC],0)) -> 0 | D7: =SUMPRODUCT((Prévisions[0]=A7)*IF(Prévisions[E / S]="Entrée",IF(ISNUMBER(Prévisions[Coût TTC]),Prévisions[Coût TTC],0),0)) -> 0 | E7: =SUMPRODUCT((Sorties[Date]=A7)*IF(ISNUMBER(Sorties[Coût TTC]),Sorties[Coût TTC],0)) -> 0 | F7: =SUMPRODUCT((Prévisions[0]=A7)*IF(Prévisions[E / S]="Sortie",IF(ISNUMBER(Prévisions[Coût TTC]),Prévisions[Coût TTC],0),0)) -> 0 | G7: =(C7+D7)-(E7+F7) -> 0 | H7: =Tresorerie!$G$2+G7 -> 1673.84 | I7: =IF(H7<0,"⛔ DÉCOUVERT",IF(H7<$C$3,"⚡ Solde faible","✅ OK")) -> ✅ OK | J7: 3
A8: =DATE(Tresorerie!$E$2,1,1)+J7 -> 46026 | B8: =TEXT(A8,"DDD") -> dim. | C8: =SUMPRODUCT((Entrées[Date]=A8)*IF(ISNUMBER(Entrées[Montant TTC]),Entrées[Montant TTC],0)) -> 0 | D8: =SUMPRODUCT((Prévisions[0]=A8)*IF(Prévisions[E / S]="Entrée",IF(ISNUMBER(Prévisions[Coût TTC]),Prévisions[Coût TTC],0),0)) -> 0 | E8: =SUMPRODUCT((Sorties[Date]=A8)*IF(ISNUMBER(Sorties[Coût TTC]),Sorties[Coût TTC],0)) -> 0 | F8: =SUMPRODUCT((Prévisions[0]=A8)*IF(Prévisions[E / S]="Sortie",IF(ISNUMBER(Prévisions[Coût TTC]),Prévisions[Coût TTC],0),0)) -> 0 | G8: =(C8+D8)-(E8+F8) -> 0 | H8: =H7+G8 -> 1673.84 | I8: =IF(H8<0,"⛔ DÉCOUVERT",IF(H8<$C$3,"⚡ Solde faible","✅ OK")) -> ✅ OK | J8: 4
A9: =DATE(Tresorerie!$E$2,1,1)+J8 -> 46027 | B9: =TEXT(A9,"DDD") -> lun. | C9: =SUMPRODUCT((Entrées[Date]=A9)*IF(ISNUMBER(Entrées[Montant TTC]),Entrées[Montant TTC],0)) -> 0 | D9: =SUMPRODUCT((Prévisions[0]=A9)*IF(Prévisions[E / S]="Entrée",IF(ISNUMBER(Prévisions[Coût TTC]),Prévisions[Coût TTC],0),0)) -> 0 | E9: =SUMPRODUCT((Sorties[Date]=A9)*IF(ISNUMBER(Sorties[Coût TTC]),Sorties[Coût TTC],0)) -> 0 | F9: =SUMPRODUCT((Prévisions[0]=A9)*IF(Prévisions[E / S]="Sortie",IF(ISNUMBER(Prévisions[Coût TTC]),Prévisions[Coût TTC],0),0)) -> 0 | G9: =(C9+D9)-(E9+F9) -> 0 | H9: =H8+G9 -> 1673.84 | I9: =IF(H9<0,"⛔ DÉCOUVERT",IF(H9<$C$3,"⚡ Solde faible","✅ OK")) -> ✅ OK | J9: 5
A10: =DATE(Tresorerie!$E$2,1,1)+J9 -> 46028 | B10: =TEXT(A10,"DDD") -> mar. | C10: =SUMPRODUCT((Entrées[Date]=A10)*IF(ISNUMBER(Entrées[Montant TTC]),Entrées[Montant TTC],0)) -> 0 | D10: =SUMPRODUCT((Prévisions[0]=A10)*IF(Prévisions[E / S]="Entrée",IF(ISNUMBER(Prévisions[Coût TTC]),Prévisions[Coût TTC],0),0)) -> 0 | E10: =SUMPRODUCT((Sorties[Date]=A10)*IF(ISNUMBER(Sorties[Coût TTC]),Sorties[Coût TTC],0)) -> 0 | F10: =SUMPRODUCT((Prévisions[0]=A10)*IF(Prévisions[E / S]="Sortie",IF(ISNUMBER(Prévisions[Coût TTC]),Prévisions[Coût TTC],0),0)) -> 0 | G10: =(C10+D10)-(E10+F10) -> 0 | H10: =H9+G10 -> 1673.84 | I10: =IF(H10<0,"⛔ DÉCOUVERT",IF(H10<$C$3,"⚡ Solde faible","✅ OK")) -> ✅ OK | J10: 6
A11: =DATE(Tresorerie!$E$2,1,1)+J10 -> 46029 | B11: =TEXT(A11,"DDD") -> mer. | C11: =SUMPRODUCT((Entrées[Date]=A11)*IF(ISNUMBER(Entrées[Montant TTC]),Entrées[Montant TTC],0)) -> 0 | D11: =SUMPRODUCT((Prévisions[0]=A11)*IF(Prévisions[E / S]="Entrée",IF(ISNUMBER(Prévisions[Coût TTC]),Prévisions[Coût TTC],0),0)) -> 0 | E11: =SUMPRODUCT((Sorties[Date]=A11)*IF(ISNUMBER(Sorties[Coût TTC]),Sorties[Coût TTC],0)) -> 10.41 | F11: =SUMPRODUCT((Prévisions[0]=A11)*IF(Prévisions[E / S]="Sortie",IF(ISNUMBER(Prévisions[Coût TTC]),Prévisions[Coût TTC],0),0)) -> 0 | G11: =(C11+D11)-(E11+F11) -> -10.41 | H11: =H10+G11 -> 1663.43 | I11: =IF(H11<0,"⛔ DÉCOUVERT",IF(H11<$C$3,"⚡ Solde faible","✅ OK")) -> ✅ OK | J11: 7
A12: =DATE(Tresorerie!$E$2,1,1)+J11 -> 46030 | B12: =TEXT(A12,"DDD") -> jeu. | C12: =SUMPRODUCT((Entrées[Date]=A12)*IF(ISNUMBER(Entrées[Montant TTC]),Entrées[Montant TTC],0)) -> 0 | D12: =SUMPRODUCT((Prévisions[0]=A12)*IF(Prévisions[E / S]="Entrée",IF(ISNUMBER(Prévisions[Coût TTC]),Prévisions[Coût TTC],0),0)) -> 0 | E12: =SUMPRODUCT((Sorties[Date]=A12)*IF(ISNUMBER(Sorties[Coût TTC]),Sorties[Coût TTC],0)) -> 0 | F12: =SUMPRODUCT((Prévisions[0]=A12)*IF(Prévisions[E / S]="Sortie",IF(ISNUMBER(Prévisions[Coût TTC]),Prévisions[Coût TTC],0),0)) -> 0 | G12: =(C12+D12)-(E12+F12) -> 0 | H12: =H11+G12 -> 1663.43 | I12: =IF(H12<0,"⛔ DÉCOUVERT",IF(H12<$C$3,"⚡ Solde faible","✅ OK")) -> ✅ OK | J12: 8
A13: =DATE(Tresorerie!$E$2,1,1)+J12 -> 46031 | B13: =TEXT(A13,"DDD") -> ven. | C13: =SUMPRODUCT((Entrées[Date]=A13)*IF(ISNUMBER(Entrées[Montant TTC]),Entrées[Montant TTC],0)) -> 0 | D13: =SUMPRODUCT((Prévisions[0]=A13)*IF(Prévisions[E / S]="Entrée",IF(ISNUMBER(Prévisions[Coût TTC]),Prévisions[Coût TTC],0),0)) -> 0 | E13: =SUMPRODUCT((Sorties[Date]=A13)*IF(ISNUMBER(Sorties[Coût TTC]),Sorties[Coût TTC],0)) -> 274.92 | F13: =SUMPRODUCT((Prévisions[0]=A13)*IF(Prévisions[E / S]="Sortie",IF(ISNUMBER(Prévisions[Coût TTC]),Prévisions[Coût TTC],0),0)) -> 0 | G13: =(C13+D13)-(E13+F13) -> -274.92 | H13: =H12+G13 -> 1388.51 | I13: =IF(H13<0,"⛔ DÉCOUVERT",IF(H13<$C$3,"⚡ Solde faible","✅ OK")) -> ✅ OK | J13: 9
A14: =DATE(Tresorerie!$E$2,1,1)+J13 -> 46032 | B14: =TEXT(A14,"DDD") -> sam. | C14: =SUMPRODUCT((Entrées[Date]=A14)*IF(ISNUMBER(Entrées[Montant TTC]),Entrées[Montant TTC],0)) -> 0 | D14: =SUMPRODUCT((Prévisions[0]=A14)*IF(Prévisions[E / S]="Entrée",IF(ISNUMBER(Prévisions[Coût TTC]),Prévisions[Coût TTC],0),0)) -> 0 | E14: =SUMPRODUCT((Sorties[Date]=A14)*IF(ISNUMBER(Sorties[Coût TTC]),Sorties[Coût TTC],0)) -> 0 | F14: =SUMPRODUCT((Prévisions[0]=A14)*IF(Prévisions[E / S]="Sortie",IF(ISNUMBER(Prévisions[Coût TTC]),Prévisions[Coût TTC],0),0)) -> 0 | G14: =(C14+D14)-(E14+F14) -> 0 | H14: =H13+G14 -> 1388.51 | I14: =IF(H14<0,"⛔ DÉCOUVERT",IF(H14<$C$3,"⚡ Solde faible","✅ OK")) -> ✅ OK | J14: 10
A15: =DATE(Tresorerie!$E$2,1,1)+J14 -> 46033 | B15: =TEXT(A15,"DDD") -> dim. | C15: =SUMPRODUCT((Entrées[Date]=A15)*IF(ISNUMBER(Entrées[Montant TTC]),Entrées[Montant TTC],0)) -> 0 | D15: =SUMPRODUCT((Prévisions[0]=A15)*IF(Prévisions[E / S]="Entrée",IF(ISNUMBER(Prévisions[Coût TTC]),Prévisions[Coût TTC],0),0)) -> 0 | E15: =SUMPRODUCT((Sorties[Date]=A15)*IF(ISNUMBER(Sorties[Coût TTC]),Sorties[Coût TTC],0)) -> 0 | F15: =SUMPRODUCT((Prévisions[0]=A15)*IF(Prévisions[E / S]="Sortie",IF(ISNUMBER(Prévisions[Coût TTC]),Prévisions[Coût TTC],0),0)) -> 0 | G15: =(C15+D15)-(E15+F15) -> 0 | H15: =H14+G15 -> 1388.51 | I15: =IF(H15<0,"⛔ DÉCOUVERT",IF(H15<$C$3,"⚡ Solde faible","✅ OK")) -> ✅ OK | J15: 11
A16: =DATE(Tresorerie!$E$2,1,1)+J15 -> 46034 | B16: =TEXT(A16,"DDD") -> lun. | C16: =SUMPRODUCT((Entrées[Date]=A16)*IF(ISNUMBER(Entrées[Montant TTC]),Entrées[Montant TTC],0)) -> 0 | D16: =SUMPRODUCT((Prévisions[0]=A16)*IF(Prévisions[E / S]="Entrée",IF(ISNUMBER(Prévisions[Coût TTC]),Prévisions[Coût TTC],0),0)) -> 0 | E16: =SUMPRODUCT((Sorties[Date]=A16)*IF(ISNUMBER(Sorties[Coût TTC]),Sorties[Coût TTC],0)) -> 0 | F16: =SUMPRODUCT((Prévisions[0]=A16)*IF(Prévisions[E / S]="Sortie",IF(ISNUMBER(Prévisions[Coût TTC]),Prévisions[Coût TTC],0),0)) -> 0 | G16: =(C16+D16)-(E16+F16) -> 0 | H16: =H15+G16 -> 1388.51 | I16: =IF(H16<0,"⛔ DÉCOUVERT",IF(H16<$C$3,"⚡ Solde faible","✅ OK")) -> ✅ OK | J16: 12
A17: =DATE(Tresorerie!$E$2,1,1)+J16 -> 46035 | B17: =TEXT(A17,"DDD") -> mar. | C17: =SUMPRODUCT((Entrées[Date]=A17)*IF(ISNUMBER(Entrées[Montant TTC]),Entrées[Montant TTC],0)) -> 0 | D17: =SUMPRODUCT((Prévisions[0]=A17)*IF(Prévisions[E / S]="Entrée",IF(ISNUMBER(Prévisions[Coût TTC]),Prévisions[Coût TTC],0),0)) -> 0 | E17: =SUMPRODUCT((Sorties[Date]=A17)*IF(ISNUMBER(Sorties[Coût TTC]),Sorties[Coût TTC],0)) -> 0 | F17: =SUMPRODUCT((Prévisions[0]=A17)*IF(Prévisions[E / S]="Sortie",IF(ISNUMBER(Prévisions[Coût TTC]),Prévisions[Coût TTC],0),0)) -> 0 | G17: =(C17+D17)-(E17+F17) -> 0 | H17: =H16+G17 -> 1388.51 | I17: =IF(H17<0,"⛔ DÉCOUVERT",IF(H17<$C$3,"⚡ Solde faible","✅ OK")) -> ✅ OK | J17: 13
A18: =DATE(Tresorerie!$E$2,1,1)+J17 -> 46036 | B18: =TEXT(A18,"DDD") -> mer. | C18: =SUMPRODUCT((Entrées[Date]=A18)*IF(ISNUMBER(Entrées[Montant TTC]),Entrées[Montant TTC],0)) -> 0 | D18: =SUMPRODUCT((Prévisions[0]=A18)*IF(Prévisions[E / S]="Entrée",IF(ISNUMBER(Prévisions[Coût TTC]),Prévisions[Coût TTC],0),0)) -> 0 | E18: =SUMPRODUCT((Sorties[Date]=A18)*IF(ISNUMBER(Sorties[Coût TTC]),Sorties[Coût TTC],0)) -> 0 | F18: =SUMPRODUCT((Prévisions[0]=A18)*IF(Prévisions[E / S]="Sortie",IF(ISNUMBER(Prévisions[Coût TTC]),Prévisions[Coût TTC],0),0)) -> 0 | G18: =(C18+D18)-(E18+F18) -> 0 | H18: =H17+G18 -> 1388.51 | I18: =IF(H18<0,"⛔ DÉCOUVERT",IF(H18<$C$3,"⚡ Solde faible","✅ OK")) -> ✅ OK | J18: 14
A19: =DATE(Tresorerie!$E$2,1,1)+J18 -> 46037 | B19: =TEXT(A19,"DDD") -> jeu. | C19: =SUMPRODUCT((Entrées[Date]=A19)*IF(ISNUMBER(Entrées[Montant TTC]),Entrées[Montant TTC],0)) -> 2197.08 | D19: =SUMPRODUCT((Prévisions[0]=A19)*IF(Prévisions[E / S]="Entrée",IF(ISNUMBER(Prévisions[Coût TTC]),Prévisions[Coût TTC],0),0)) -> 0 | E19: =SUMPRODUCT((Sorties[Date]=A19)*IF(ISNUMBER(Sorties[Coût TTC]),Sorties[Coût TTC],0)) -> 2.99 | F19: =SUMPRODUCT((Prévisions[0]=A19)*IF(Prévisions[E / S]="Sortie",IF(ISNUMBER(Prévisions[Coût TTC]),Prévisions[Coût TTC],0),0)) -> 0 | G19: =(C19+D19)-(E19+F19) -> 2194.09 | H19: =H18+G19 -> 3582.6 | I19: =IF(H19<0,"⛔ DÉCOUVERT",IF(H19<$C$3,"⚡ Solde faible","✅ OK")) -> ✅ OK | J19: 15
... A369: =DATE(Tresorerie!$E$2,1,1)+J368 -> 46387 | B369: =TEXT(A369,"DDD") -> jeu. | C369: =SUMPRODUCT((Entrées[Date]=A369)*IF(ISNUMBER(Entrées[Montant TTC]),Entrées[Montant TTC],0)) -> 0 | D369: =SUMPRODUCT((Prévisions[0]=A369)*IF(Prévisions[E / S]="Entrée",IF(ISNUMBER(Prévisions[Coût TTC]),Prévisions[Coût TTC],0),0)) -> 0 | E369: =SUMPRODUCT((Sorties[Date]=A369)*IF(ISNUMBER(Sorties[Coût TTC]),Sorties[Coût TTC],0)) -> 0 | F369: =SUMPRODUCT((Prévisions[0]=A369)*IF(Prévisions[E / S]="Sortie",IF(ISNUMBER(Prévisions[Coût TTC]),Prévisions[Coût TTC],0),0)) -> 0 | G369: =(C369+D369)-(E369+F369) -> 0 | H369: =H368+G369 -> -12260.44 | I369: =IF(H369<0,"⛔ DÉCOUVERT",IF(H369<$C$3,"⚡ Solde faible","✅ OK")) -> ⛔ DÉCOUVERT | J369: 365
J370: 365
A371: ▶ SYNTHÈSE ANNUELLE DES RISQUES | J371: 365
A372: Nombre de jours en découvert | H372: =COUNTIF(H5:H369,"<0") -> 170 | J372: 365
A373: Nombre de jours en alerte ⚡ | H373: =COUNTIFS(H5:H369,"<"&$C$3) -> 231 | J373: 365
A374: Solde minimum atteint (€) | H374: =MIN(H5:H369) -> -12260.44 | J374: 365
A375: Solde maximum atteint (€) | H375: =MAX(H5:H369) -> 3582.6 | J375: 365
A376: Solde moyen sur l'année (€) | H376: =AVERAGE(H5:H369) -> -928.73581 | J376: 365
A377: Solde final (31 déc.) (€) | H377: =H369 -> -12260.44 | J377: 365

Sheet Inventaire
A1: Référence | B1: Quantité | C1: Prix achat | D1: Prix Location
A2: LIGHTS
A3: Laser 10W OPT | B3: 4 | C3: 818.09€ | D3: 200
A4: Laser 10W OPT | B4: 2 | C4: 769.36€
A5: Blinder 2 Eyes | B5: 4 | C5: 88.41€ | D5: 30
A6: Blinder 2 Eyes | B6: 2 | C6: 68.41€
A7: PAR 18x18 | B7: 8 | C7: 82.16€ | D7: 20
A8: Fos Tornado pro | B8: 5 | C8: 570.00€ | D8: 80
A9: Shehds 10R | B9: 8 | C9: 452.39€ | D9: 70
A10: Shehds 10R | B10: 4 | C10: 397.23€
A11: Shehds 19x15 | B11: 6 | C11: 311.21€ | D11: 60
A12: Shehds 19x15 | B12: 2 | C12: 280.40€
A13: Shehds bar 12x40W | B13: 4 | C13: 439.76€ | D13: 100
A14: CONSOLE LIGHT
A15: APC MINI MKII | B15: 1 | C15: 95.00€
A16: Sunlite EC | B16: 1 | C16: 419.00€
A17: Extension sunlite | B17: 1 | C17: 225.34
A18: Boitier FB4 | B18: 1 | C18: 682.50€ | D18: 120
A19: Estop | B19: 1 | C19: 27.30€
A20: Boitier FB4 | B20: 1 | C20: 641.85€
A24: Rallonges
A25: Touret 30m renf | B25: 2 | C25: 59.9
A26: Rallonges 10m renf | B26: 3 | C26: 26.9
A27: Rallonges 5m | B27: 3 | C27: 6.9
A28: Rallonges 5m double | B28: 1 | C28: 16.9
A29: Multiprise 5p | B29: 2 | C29: 4.9
A30: Multiprise 5p renf | B30: 5 | C30: 8.9
A31: Multiprise triplette | B31: 3 | C31: 2.5
A32: Multiprises
A36: Armoires Electrique
A37: Armoire T32A | B37: 2 | D37: 45
A38: Armoire T16A | B38: 1 | D38: 40
A41: Structure
A42: Pieds laser avec sacoche | B42: 4 | C42: 30 | D42: =125*0.95 -> 118.75
A43: Crochets BC50B-150F | B43: 4 | C43: 16.5 | D43: 16.5
A44: Crochets BC50B-150F | B44: 10 | C44: 16 | D44: 16
A45: Elingue | B45: 20 | C45: 3.5 | D45: 3.5
A46: Passe câbles 1m | B46: 10 | D46: 8
A50: CABLE DMX
A51: Touret | B51: 5 | C51: 15.90€ | D51: 15.90€
...

Sheet CACHE GRAPH
B1: DÉPENSES RÉELLES | C1: ENTRÉES RÉELLES | D1: RÉSULTAT NET RÉEL | E1: SOLDE RÉEL CUMULÉ | F1: TOTAL DÉPENSES PRÉV | G1: TOTAL ENTRÉES PRÉV | H1: SOLDE PROJETÉ CUMULÉ
A2: Janvier | B2: =Dashboard!$B$10 -> 3693.82 | C2: =Dashboard!$B$11 -> 2197.08 | D2: =Dashboard!$B$12 -> -1496.74 | E2: =Dashboard!$B$10 -> 3693.82 | F2: =Dashboard!$B$14 -> 0 | G2: =Dashboard!$B$15 -> 0 | H2: =Dashboard!$B$16 -> 177.1
A3: Fevrier | B3: =Dashboard!$C$10 -> 1270.44 | C3: =Dashboard!$C$11 -> 2530.07 | D3: =Dashboard!$C$12 -> 1259.63 | E3: =Dashboard!$C$13 -> 1436.73 | F3: =Dashboard!$C$14 -> 0 | G3: =Dashboard!$C$15 -> 0 | H3: =Dashboard!$C$16 -> 1436.73
A4: Mars | B4: =Dashboard!$D$10 -> 1416.39 | C4: =Dashboard!$D$11 -> 1179.84 | D4: =Dashboard!$D$12 -> -236.55 | E4: =Dashboard!$D$13 -> 1200.18 | F4: =Dashboard!$D$14 -> 0 | G4: =Dashboard!$D$15 -> 0 | H4: =Dashboard!$D$16 -> 1200.18
A5: Avril | B5: =Dashboard!$E$10 -> 1472.04 | C5: =Dashboard!$E$11 -> 1780.4 | D5: =Dashboard!$E$12 -> 308.36 | E5: =Dashboard!$E$13 -> 1508.54 | F5: =Dashboard!$E$14 -> 0 | G5: =Dashboard!$E$15 -> 0 | H5: =Dashboard!$E$16 -> 1508.54
A6: Mai | B6: =Dashboard!$F$10 -> 468.99 | C6: =Dashboard!$F$11 -> 906.13 | D6: =Dashboard!$F$12 -> 437.14 | E6: =Dashboard!$F$13 -> 1945.68 | F6: =Dashboard!$F$14 -> 1697.99 | G6: =Dashboard!$F$15 -> 0 | H6: =Dashboard!$F$16 -> 247.69
A7: Juin | B7: =Dashboard!$G$10 -> 0 | C7: =Dashboard!$G$11 -> 0 | D7: =Dashboard!$G$12 -> 0 | E7: =Dashboard!$G$13 -> 1945.68 | F7: =Dashboard!$G$14 -> 2412.99 | G7: =Dashboard!$G$15 -> 325.8 | H7: =Dashboard!$G$16 -> -1839.5
A8: Juillet | B8: =Dashboard!$H$10 -> 0 | C8: =Dashboard!$H$11 -> 0 | D8: =Dashboard!$H$12 -> 0 | E8: =Dashboard!$H$13 -> 1945.68 | F8: =Dashboard!$H$14 -> 242.99 | G8: =Dashboard!$H$15 -> 1500 | H8: =Dashboard!$H$16 -> -582.49
A9: Aout | B9: =Dashboard!$I$10 -> 0 | C9: =Dashboard!$I$11 -> 0 | D9: =Dashboard!$I$12 -> 0 | E9: =Dashboard!$I$13 -> 1945.68 | F9: =Dashboard!$I$14 -> 2542.99 | G9: =Dashboard!$I$15 -> 1327 | H9: =Dashboard!$I$16 -> -1798.48
A10: Septembre | B10: =Dashboard!$J$10 -> 0 | C10: =Dashboard!$J$11 -> 0 | D10: =Dashboard!$J$12 -> 0 | E10: =Dashboard!$J$13 -> 1945.68 | F10: =Dashboard!$J$14 -> 1902.99 | G10: =Dashboard!$J$15 -> 3000 | H10: =Dashboard!$J$16 -> -701.47
A11: Octobre | B11: =Dashboard!$K$10 -> 0 | C11: =Dashboard!$K$11 -> 0 | D11: =Dashboard!$K$12 -> 0 | E11: =Dashboard!$K$13 -> 1945.68 | F11: =Dashboard!$K$14 -> 702.99 | G11: =Dashboard!$K$15 -> 0 | H11: =Dashboard!$K$16 -> -1404.46
A12: Novembre | B12: =Dashboard!$L$10 -> 0 | C12: =Dashboard!$L$11 -> 0 | D12: =Dashboard!$L$12 -> 0 | E12: =Dashboard!$L$13 -> 1945.68 | F12: =Dashboard!$L$14 -> 3852.99 | G12: =Dashboard!$L$15 -> 0 | H12: =Dashboard!$L$16 -> -5257.45
A13: Décembre | B13: =Dashboard!$M$10 -> 0 | C13: =Dashboard!$M$11 -> 0 | D13: =Dashboard!$M$12 -> 0 | E13: =Dashboard!$M$13 -> 1945.68 | F13: =Dashboard!$M$14 -> 7002.99 | G13: =Dashboard!$M$15 -> 0 | H13: =Dashboard!$M$16 -> -12260.44

Sheet CACHE
A1: Dépenses | E1: Recettes | I1: Prévisions
A2: Matériel | B2: Frais_Fixes | C2: Frais_Techniques | D2: Frais_Artistiques | E2: Prestation_Tech | F2: Vente_Materiel | G2: Recettes_Evenement | H2: Remboursement | I2: Matériel | J2: Frais_Fixes | K2: Frais_Techniques | L2: Frais_Artistiques | M2: Prestation_Tech | N2: Vente_Materiel | O2: Recettes_Evenement | P2: Remboursement
A3: Achat de matériel | B3: Frais IT | C3: Techniciens | D3: Booking DJ | E3: Location de matériel | F3: Vente de Materiel | G3: Recettes Evenement | H3: Remboursement | I3: Achat de matériel | J3: Frais IT | K3: Techniciens | L3: Booking DJ | M3: Location de matériel | N3: Vente_Materiel | O3: Recettes_Evenement | P3: Remboursement
A4: Frais Entretien | B4: Google Drive | C4: Transport | D4: Photographe/Vidéaste | E4: Techniciens | I4: Frais Entretien | J4: Google Drive | K4: Transport | L4: Photographe/Vidéaste | M4: Techniciens
A5: Location de matériel | B5: Site Internet | C5: Salle | D5: DA/Graphiste | I5: Location de matériel | J5: Site Internet | L5: DA/Graphiste
B6: Local | D6: Communication | J6: Local
B7: Assurance | J7: Assurance
B8: Frais Bancaires | J8: Frais Bancaires
