Workbook

Sheet Global
A1: 2024 | B1: Aout 2024 | C1: Septembre 2024 | D1: Octobre 2024 | E1: Novembre 2024 | F1: Decembre 2024
A2: Entrées | B2: =Aout2024!C4 -> 4650 | C2: =Sept2024!C4 -> 101 | D2: ='Oct2024'!C4 -> 0 | E2: ='Nov2024'!C5 -> 9228.01 | F2: ='Dec2024'!C4 -> 0
A3: Prestation
A4: Don
I5: Chiffre d'Affaire | J5: Bénéfices
A6: Sorties | B6: =Aout2024!C9 -> 4624.89 | C6: =Sept2024!C8 -> 125.28 | D6: ='Oct2024'!C8 -> 0 | E6: ='Nov2024'!C22 -> 8621 | F6: ='Dec2024'!C9 -> 295 | H6: 2024 | I6: =SUM(B2:F2) -> 13979.01 | J6: =SUM(B8:F8) -> 312.84
H7: 2025 | I7: =SUM(B13:M13) -> 23905.05 | J7: =SUM(A16:M17) -> 1361
A8: Bénéfices | B8: =B2-B6 -> 25.11 | C8: =C2-C6 -> -24.28 | D8: =D2-D6 -> 0 | E8: =E2-E6 -> 607.01 | F8: =F2-F6 -> -295 | I8: =I6+I7 -> 37884.06
A9: Trésorie fin de mois | B9: =B8 -> 25.11 | C9: =B9+C8 -> 0.83 | D9: =C9+D8 -> 0.83 | E9: =D9+E8 -> 607.84 | F9: =E9+F8 -> 312.84
A12: 2025 | B12: Janvier 2025 | C12: Février 2025 | D12: Mars 2025 | E12: Avril 2025 | F12: Mai 2025 | G12: Juin 2025 | H12: Juillet 2025 | I12: Aout 2025 | J12: Septembre 2025 | K12: Octobre 2025 | L12: Novembre 2025 | M12: Decembre 2025
A13: Entrées | B13: ='Janvier 2025'!C6 -> 249 | C13: ='Février 2025'!C4 -> 0 | D13: ='Mars 2025'!C9 -> 1620 | E13: ='Avril 2025'!C5 -> 550 | F13: ='Mai 2025'!C7 -> 330 | G13: ='Juin 2025'!C6 -> 0 | H13: ='Juillet 2025'!C7 -> 1123 | I13: ='Aout 2025'!C5 -> 0 | J13: ='Septembre 2025'!C10 -> 941.65 | K13: ='Octobre 2025'!C15 -> 0 | L13: ='Novembre 2025'!C15 -> 9732.9 | M13: ='Decembre 2025'!C13 -> 9358.5
A15: Sorties | B15: ='Janvier 2025'!C11 -> 203.4 | C15: ='Février 2025'!C8 -> 0 | D15: ='Mars 2025'!C16 -> 1886.69 | E15: ='Avril 2025'!C12 -> 25.74 | F15: ='Mai 2025'!C17 -> 382.77 | G15: ='Juin 2025'!C14 -> 158.08 | H15: ='Juillet 2025'!C14 -> 552.7 | I15: ='Aout 2025'!C17 -> 265.54 | J15: ='Septembre 2025'!C23 -> 1279.67 | K15: ='Octobre 2025'!C29 -> 361.57 | L15: ='Novembre 2025'!C30 -> 9529.15 | M15: ='Decembre 2025'!C29 -> 7898.74
A17: Bénéfices | B17: =B13-B15 -> 45.6 | C17: =C13-C15 -> 0 | D17: =D13-D15 -> -266.69 | E17: =E13-E15 -> 524.26 | F17: =F13-F15 -> -52.77 | G17: =G13-G15 -> -158.08 | H17: =H13-H15 -> 570.3 | I17: =I13-I15 -> -265.54 | ... M17: =M13-M15 -> 1459.76
A18: Trésorie fin de mois | B18: =F9+B17 -> 358.44 | C18: =C17+B18 -> 358.44 | D18: =D17+C18 -> 91.75 | E18: =E17+D18 -> 616.01 | F18: =F17+E18 -> 563.24 | G18: =G17+F18 -> 405.16 | H18: =H17+G18 -> 975.46 | I18: =I17+H18 -> 709.92 | J18: =J17+I18 -> 371.9 | ... M18: =M17+L18 -> 1673.84
B21: Bilan Comptable 2024 | G21: Bilan 2024
B22: Actif | C22: Montant (euros) | D22: Passif | E22: Montant (euros) | G22: Location | H22: =Aout2024!$I$2 + Sept2024!$I$2 + 'Oct2024'!$I$2 + 'Nov2024'!$I$2 + 'Dec2024'!$I$2 -> 0 | I22: Frais | J22: =Aout2024!$K$2 + Sept2024!$K$2 + 'Oct2024'!$K$2 + 'Nov2024'!$K$2 + 'Dec2024'!$K$2 -> 322.29
B23: Actifs circulants | C23: =C24 -> 312.84 | D23: Capitaux propres | E23: =E25+E26+E27+E28 -> 4073.84 | G23: Vente | H23: =Aout2024!$I$3 + Sept2024!$I$3 + 'Oct2024'!$I$3 + 'Nov2024'!$I$3 + 'Dec2024'!$I$3 -> 0 | I23: Achat Matériel | J23: =Aout2024!$K$3 + Sept2024!$K$3 + 'Oct2024'!$K$3 + 'Nov2024'!$K$3 + 'Dec2024'!$K$3 -> 13295.73
B24: Trésorerie | C24: =F9 -> 312.84 | D24: Résultat de l'exercice | E24: =C41 -> 312.84 | G24: Prestation | H24: =Aout2024!$I$4 + Sept2024!$I$4 + 'Oct2024'!$I$4 + 'Nov2024'!$I$4 + 'Dec2024'!$I$4 -> 13850 | I24: Location | J24: =Aout2024!$K$4 + Sept2024!$K$4 + 'Oct2024'!$K$4 + 'Nov2024'!$K$4 + 'Dec2024'!$K$4 -> 48.15
B25: Actifs immobilisés | C25: =SUM(C26:C27) -> 17326 | D25: Résultats accumulés | E25: =F9 -> 312.84 | G25: Remboursement | H25: =Aout2024!$I$5 + Sept2024!$I$5 + 'Oct2024'!$I$5 + 'Nov2024'!$I$5 + 'Dec2024'!$I$5 -> 28.01
B26: Immobilisations corporelles | C26: =17326-'Nov2024'!C18 -> 17100.66 | D26: Apports des membres | E26: =H26 -> 101 | G26: Don | H26: =Aout2024!$I$6 + Sept2024!$I$6 + 'Oct2024'!$I$6 + 'Nov2024'!$I$6 + 'Dec2024'!$I$6 -> 101
B27: Immobilisations incorporelles | C27: ='Nov2024'!C18 -> 225.34 | D27: Apports matériel des membres | E27: 3660
D28: Subventions d’investissement | E28: 0
D29: Dettes | E29: =SUM(E30) -> 0
D30: Emprunts et autres dettes | E30: 0
B31: Total Actifs | C31: =C25+C23 -> 17638.84 | D31: Total Passifs | E31: =E23+E29 -> 4073.84
B33: Compte de résultat pour l'exercice 2024
B34: Charges | C34: Montant (euros) | D34: Produits | E34: Montant (euros)
B35: Frais banquaires | C35: =J22 -> 322.29 | D35: Prestations de production | E35: =H24 -> 13850
B36: Frais administratifs | C36: 0 | D36: Vente de matériel | E36: =H23 -> 0
B37: Achat de matériel | C37: =J23 -> 13295.73 | D37: Location de matériel | E37: =H22 -> 0
B38: Location de matériel | C38: =J24 -> 48.15 | D38: Subventions et dons | E38: =H26 -> 101
D39: Autres produits | E39: =H25 -> 28.01
B40: Total Charges | C40: =SUM(C35:C39) -> 13666.17 | D40: Total Produits | E40: =SUM(E35:E39) -> 13979.01
B41: Resultat Net | C41: =E40-C40 -> 312.84
B47: Bilan Comptable 2025 | G47: Bilan 2025
B48: Actif | C48: Montant (euros) | D48: Passif | E48: Montant (euros) | G48: Location | H48: ='Janvier 2025'!I2 + 'Février 2025'!I2 + 'Mars 2025'!I2 + 'Avril 2025'!I2 + 'Mai 2025'!I2 + 'Juin 2025'!I2 + 'Juillet 2025'!I2 + 'Aout 2025'!I2 + 'Septembre 2025'!I2 + 'Octobre 2025'!I2 + 'Novembre 2025'!I2 + 'Decembre 2025'!I2 -> 528 | I48: Frais | J48: ='Janvier 2025'!K2 + 'Février 2025'!K2 + 'Mars 2025'!K2 + 'Avril 2025'!K2 + 'Mai 2025'!K2 + 'Juin 2025'!K2 + 'Juillet 2025'!K2 + 'Aout 2025'!K2 + 'Septembre 2025'!K2 + 'Octobre 2025'!K2 + 'Novembre 2025'!K2 + 'Decembre 2025'!K2 -> 455.91
B49: Actifs circulants | C49: =C50 -> 1673.84 | D49: Capitaux propres | E49: =SUM(E50:E54) -> 34376.5 | G49: Vente | H49: ='Janvier 2025'!I3 + 'Février 2025'!I3 + 'Mars 2025'!I3 + 'Avril 2025'!I3 + 'Mai 2025'!I3 + 'Juin 2025'!I3 + 'Juillet 2025'!I3 + 'Aout 2025'!I3 + 'Septembre 2025'!I3 + 'Octobre 2025'!I3 + 'Novembre 2025'!I3 + 'Decembre 2025'!I3 -> 249 | I49: Achat Matériel | J49: ='Janvier 2025'!K3 + 'Février 2025'!K3 + 'Mars 2025'!K3 + 'Avril 2025'!K3 + 'Mai 2025'!K3 + 'Juin 2025'!K3 + 'Juillet 2025'!K3 + 'Aout 2025'!K3 + 'Septembre 2025'!K3 + 'Octobre 2025'!K3 + 'Novembre 2025'!K3 + 'Decembre 2025'!K3 -> 16275.69
B50: Trésorerie | C50: =M18 -> 1673.84 | D50: Résultat de l'exercice | E50: =C67 -> 1361 | G50: Prestation | H50: ='Janvier 2025'!I4 + 'Février 2025'!I4 + 'Mars 2025'!I4 + 'Avril 2025'!I4 + 'Mai 2025'!I4 + 'Juin 2025'!I4 + 'Juillet 2025'!I4 + 'Aout 2025'!I4 + 'Septembre 2025'!I4 + 'Octobre 2025'!I4 + 'Novembre 2025'!I4 + 'Decembre 2025'!I4 -> 22988.05 | I50: Location | J50: ='Janvier 2025'!K4 + 'Février 2025'!K4 + 'Mars 2025'!K4 + 'Avril 2025'!K4 + 'Mai 2025'!K4 + 'Juin 2025'!K4 + 'Juillet 2025'!K4 + 'Aout 2025'!K4 + 'Septembre 2025'!K4 + 'Octobre 2025'!K4 + 'Novembre 2025'!K4 + 'Decembre 2025'!K4 -> 5812.45
B51: Actifs immobilisés | C51: =SUM(C52:C53) -> 32702.66 | D51: Résultats accumulés | E51: =C57-E50-E52-E53-E54 -> 29215.5 | G51: Remboursement | H51: ='Janvier 2025'!I5 + 'Février 2025'!I5 + 'Mars 2025'!I5 + 'Avril 2025'!I5 + 'Mai 2025'!I5 + 'Juin 2025'!I5 + 'Juillet 2025'!I5 + 'Aout 2025'!I5 + 'Septembre 2025'!I5 + 'Octobre 2025'!I5 + 'Novembre 2025'!I5 + 'Decembre 2025'!I5 -> 0
B52: Immobilisations corporelles | C52: 32477.32 | D52: Apports des membres | E52: =H52 -> 140 | G52: Don | H52: ='Janvier 2025'!I6 + 'Février 2025'!I6 + 'Mars 2025'!I6 + 'Avril 2025'!I6 + 'Mai 2025'!I6 + 'Juin 2025'!I6 + 'Juillet 2025'!I6 + 'Aout 2025'!I6 + 'Septembre 2025'!I6 + 'Octobre 2025'!I6 + 'Novembre 2025'!I6 + 'Decembre 2025'!I6 -> 140
...

Sheet Decembre 2025
A1: Objet | B1: Nature | C1: Montant | D1: Lien Facture | E1: Date | F1: Référence transaction | H1: Bilan
A2: Entrées | H2: Location entrée | I2: =SUMIF(B:B, H2, C:C) -> 0 | J2: Frais | K2: =SUMIF(B:B, J2, C:C) -> 2.99
A3: Solde gala ISAE | B3: Prestation | C3: 8434.5 | E3: 46007 | H3: Vente | I3: =SUMIF(B:B, H3, C:C) -> 0 | J3: Achat Matériel | K3: =SUMIF(B:B, J3, C:C) -> 4124.93
A4: AAW | B4: Prestation | C4: 924 | E4: 46010 | H4: Prestation | I4: =SUMIF(B:B, H4, C:C) -> 9358.5 | J4: Location sortie | K4: =SUMIF(B:B, J4, C:C) -> 3770.82
H5: Remboursement | I5: =SUMIF(B:B, H5, C:C) -> 0
H6: Don
A13: Total Entrées | C13: =SUM(C3:C12) -> 9358.5
A15: Sorties
A16: Tout le haut parleur | B16: Achat Matériel | C16: 79.36 | E16: 45992
A17: Location Xone | B17: Location sortie | C17: 80 | E17: 46007
A18: Audiotec | B18: Location sortie | C18: 843.82 | E18: 46007
A19: Paiement tech | B19: Location sortie | C19: 900 | E19: 46007
A20: Location Xone | B20: Location sortie | C20: 80 | E20: 46007
A21: Paiement tech | B21: Location sortie | C21: 900 | E21: 46007
A22: Paiement tech | B22: Location sortie | C22: 450 | E22: 46007
A23: Paiement photo Anton | B23: Location sortie | C23: 317 | E23: 46007
A24: Paiement dj Tabata | B24: Location sortie | C24: 200 | E24: 46007
A25: Paiement NDF Shehds | B25: Achat Matériel | C25: 4045.57 | E25: 46009
A26: Abo google | B26: Frais | C26: 2.99 | E26: 46009
A29: Total Sorties | C29: =SUM(C16:C28) -> 7898.74

Sheet Novembre 2025
A1: Objet | B1: Nature | C1: Montant | D1: Lien Facture | E1: Date | F1: Référence transaction | H1: Bilan
A2: Entrées | H2: Location entrée | I2: =SUMIF(B:B, H2, C:C) -> 0 | J2: Frais | K2: =SUMIF(B:B, J2, C:C) -> 29.9
A3: Acompte GALA ISAE | B3: Prestation | C3: 9228.5 | D3: 2025-10-27 Acompte GALA ISAE | E3: 45964 | H3: Vente | I3: =SUMIF(B:B, H3, C:C) -> 0 | J3: Achat Matériel | K3: =SUMIF(B:B, J3, C:C) -> 9348.4
A4: Reparation BDA ISAE | B4: Prestation | C4: 196.4 | E4: 45988 | H4: Prestation | I4: =SUMIF(B:B, H4, C:C) -> 9732.9 | J4: Location sortie | K4: =SUMIF(B:B, J4, C:C) -> 150.85
A5: Location BDE ISAE | B5: Prestation | C5: 308 | E5: 45980 | H5: Remboursement | I5: =SUMIF(B:B, H5, C:C) -> 0
H6: Don | I6: =SUMIF(B:B, H6, C:C) -> 0
A15: Total Entrées | C15: =SUM(C3:C14) -> 9732.9
A17: Sorties
A18: Audiotec SON | B18: Location sortie | C18: 150.85 | D18: 2025-11-03 Audiotec.pdf | E18: 45964
A19: BAX | B19: Achat matériel | C19: 156.4 | D19: BAX-INV-31093614.pdf | E19: 45964
A20: OPT LASER | B20: Achat matériel | C20: 2738.05 | D20: 2025-11-03 OPT LASER.pdf | E20: 45965
A21: Frais Lasers | B21: Frais | C21: 26.91 | E21: 45965
A22: Prozic | B22: Achat matériel | C22: 112.66 | D22: 2025-11-11 Prozic.pdf | E22: 45972
A23: Audiotec CDJ3000X | B23: Achat matériel | C23: 5625 | E23: 45967
A24: Abo google | B24: Frais | C24: 2.99 | E24: 45976
A25: Prozic | B25: Achat matériel | C25: 707.9 | E25: 45980
A26: Amazon | B26: Achat matériel | C26: 8.39 | E26: 45988
A30: Total Sorties | C30: =SUM(C18:C29) -> 9529.15

Sheet Octobre 2025
A1: Objet | B1: Nature | C1: Montant | D1: Lien Facture | E1: Date | F1: Référence transaction | H1: Bilan
A2: Entrées | H2: Location entrée | I2: =SUMIF(B:B, H2, C:C) -> 0 | J2: Frais | K2: =SUMIF(B:B, J2, C:C) -> 2.99
H3: Vente | I3: =SUMIF(B:B, H3, C:C) -> 0 | J3: Achat Matériel | K3: =SUMIF(B:B, J3, C:C) -> 288.58
H4: Prestation | I4: =SUMIF(B:B, H4, C:C) -> 0 | J4: Location sortie | K4: =SUMIF(B:B, J4, C:C) -> 70
H5: Remboursement | I5: =SUMIF(B:B, H5, C:C) -> 0
H6: Don | I6: =SUMIF(B:B, H6, C:C) -> 0
A15: Total Entrées | C15: =SUM(C3:C14) -> 0
A17: Sorties
A18: Amazon - Etain | B18: Achat matériel | C18: 13.99 | D18: 2025-10-29 Amazon.pdf | E18: 45959
A19: Audiotec | B19: Achat matériel | C19: 173.65 | D19: AUDIOTEC.pdf | E19: 45936
A20: Aliexpress fiches dmx/powercon | B20: Achat matériel | C20: 100.94 | E20: 45957
A21: Abonnement google | B21: Frais | C21: 2.99 | E21: 45945
A22: AE | B22: Location sortie | C22: 70 | D22: 2025-11-07 AE.pdf | E22: 45959
A29: Total Sorties | C29: =SUM(C18:C28) -> 361.57

Sheet Septembre 2025
A1: Objet | B1: Nature | C1: Montant | D1: Lien Facture | E1: Date | F1: Référence transaction | H1: Bilan
A2: Entrées | H2: Location entrée | I2: =SUMIF(B:B, H2, C:C) -> 130 | J2: Frais | K2: =SUMIF(B:B, J2, C:C) -> 132.59
A3: AAW 1/2 | B3: Prestation | C3: 712.65 | E3: 45929 | H3: Vente | I3: =SUMIF(B:B, H3, C:C) -> 0 | J3: Achat Matériel | K3: =SUMIF(B:B, J3, C:C) -> 0
A4: Equilibrage FDM - AAW | B4: Remboursement | C4: 315! | H4: Prestation | I4: =SUMIF(B:B, H4, C:C) -> 811.65 | J4: Location sortie | K4: =SUMIF(B:B, J4, C:C) -> 1147.08
A5: ISAE | B5: Location entrée | C5: 130 | E5: 45912 | H5: Remboursement | I5: =SUMIF(B:B, H5, C:C) -> 0
A6: Big Bazar Festival 2025 | B6: Prestation | C6: 99 | E6: 45903 | H6: Don | I6: =SUMIF(B:B, H6, C:C) -> 0
A10: Total Entrées | C10: =SUM(C3:C9) -> 941.65
A12: Sorties
A13: Quonto | B13: Frais | C13: 129.6 | E13: 45901
A14: GIFI | B14: Location sortie | C14: 165 | E14: 45904
A15: Audiotec | B15: Location sortie | C15: 660.28 | D15: 2025-09-23 Audiotec.pdf | E15: 45929
A16: ISAE | B16: Location sortie | C16: 45 | D16: 2025-08-30 ISAE.pdf | E16: 45903
A17: Audiotec | B17: Location sortie | C17: 71.76 | D17: 2025-08-30 Audiotec | E17: 45903
A18: Audiotec | B18: Location sortie | C18: 91.26 | D18: 2025-09-09 Audiotec.pdf | E18: 45912
A19: Abonnement google | B19: Frais | C19: 2.99 | E19: 45915
A20: Audiotec | B20: Location sortie | C20: 113.78 | D20: 2025-09-19 Audiotec.pdf | E20: 45903
A23: Total Sorties | C23: =SUM(C13:C22) -> 1279.67

Sheet Aout 2025
A1: Objet | B1: Nature | C1: Montant | D1: Lien Facture | E1: Date | F1: Référence transaction | H1: Bilan
A2: Entrées | H2: Location entrée | I2: =SUMIF(B:B, H2, C:C) -> 0 | J2: Frais | K2: =SUMIF(B:B, J2, C:C) -> 0.75
H3: Vente | I3: =SUMIF(B:B, H3, C:C) -> 0 | J3: Achat Matériel | K3: =SUMIF(B:B, J3, C:C) -> 264.79
H4: Prestation | I4: =SUMIF(B:B, H4, C:C) -> 0 | J4: Location sortie | K4: =SUMIF(B:B, J4, C:C) -> 0
A5: Total Entrées | C5: =SUM(C3:C4) -> 0 | H5: Remboursement | I5: =SUMIF(B:B, H5, C:C) -> 0
H6: Don | I6: =SUMIF(B:B, H6, C:C) -> 0
A7: Sorties
A8: HP - remp casse FDM | B8: Achat matériel | C8: 256.79 | D8: 2025-08-05 Tout le haut parleur.pdf | E8: 45870
A9: Audiotec | B9: Achat matériel | C9: 8 | D9: 2025-08-18 Audiotec.pdf | E9: 45887
A12: Google | B12: Frais | C12: 0.75
A17: Total Sorties | C17: =SUM(C8:C16) -> 265.54

Sheet Juillet 2025
A1: Objet | B1: Nature | C1: Montant | D1: Lien Facture | E1: Date | F1: Référence transaction | H1: Bilan
A2: Entrées | H2: Location entrée | I2: =SUMIF(B:B, H2, C:C) -> 68 | J2: Frais | K2: =SUMIF(B:B, J2, C:C) -> 0
A3: Presta 10AM | B3: Prestation | C3: 455 | D3: Facture_000010_DEJA_VU_10AM.pdf | E3: 45841 | H3: Vente | I3: =SUMIF(B:B, H3, C:C) -> 0 | J3: Achat Matériel | K3: =SUMIF(B:B, J3, C:C) -> 0
A4: Loc AC - 10R | B4: Location entrée | C4: 68 | D4: 2025-08-07 Acoustic Color.pdf | E4: 45847 | H4: Prestation | I4: =SUMIF(B:B, H4, C:C) -> 1055 | J4: Location sortie | K4: =SUMIF(B:B, J4, C:C) -> 552.7
A5: Presta Bastien | B5: Prestation | C5: 600 | D5: 2025-08-13 Lapointe Bastien.pdf | E5: 45868 | H5: Remboursement | I5: =SUMIF(B:B, H5, C:C) -> 0
H6: Don | I6: =SUMIF(B:B, H6, C:C) -> 0
A7: Total Entrées | C7: =SUM(C3:C6) -> 1123
A9: Sorties
A10: Location Prosodie | B10: Location sortie | C10: 216 | D10: 2025-07-07 PROSODIE.pdf | E10: 45846
A11: Location Audiotec | B11: Location sortie | C11: 221.7 | D11: 2025-07-03 Audiotec.pdf | E11: 45846
A12: BAZAR - loc DAS 218 | B12: Location sortie | C12: 115 | D12: 2025-07-08 Bazar.pdf | E12: 45847
A14: Total Sorties | C14: =SUM(C10:C13) -> 552.7

Sheet Juin 2025
A1: g | B1: Nature | C1: Montant | D1: Lien Facture | E1: Date | F1: Référence transaction | H1: Bilan
A2: Entrées | H2: Location entrée | I2: =SUMIF(B:B, H2, C:C) -> 0 | J2: Frais | K2: =SUMIF(B:B, J2, C:C) -> 0
H3: Vente | I3: =SUMIF(B:B, H3, C:C) -> 0 | J3: Achat Matériel | K3: =SUMIF(B:B, J3, C:C) -> 158.08
H4: Prestation | I4: =SUMIF(B:B, H4, C:C) -> 0 | J4: Location sortie | K4: =SUMIF(B:B, J4, C:C) -> 0
H5: Remboursement | I5: =SUMIF(B:B, H5, C:C) -> 0
A6: Total Entrées | C6: =SUM(C3:C5) -> 0 | H6: Don | I6: =SUMIF(B:B, H6, C:C) -> 0
A8: Sorties
A9: Audiotec | B9: Achat matériel | C9: 84.08 | D9: 2025-06-11 Audiotec.pdf | E9: 45819
A10: Bricoman | B10: Achat matériel | C10: 7.3 | D10: 2026-06-14 BRICOMAN.pdf | E10: 45822
A11: Thomann | B11: Achat matériel | C11: 66.7 | D11: 2025-06-20 Thomann.pdf | E11: 45824
A12: AC - pret machine bulle | B12: Location sortie | C12: 0 | D12: 2025-06-27 Pret Acoustic Color.pdf
A14: Total Sorties | C14: =SUM(C9:C13) -> 158.08

Sheet Mai 2025
A1: Objet | B1: Nature | C1: Montant | D1: Lien Facture | E1: Date | F1: Référence transaction | H1: Bilan
A2: Entrées | H2: Location entrée | I2: =SUMIF(B:B, H2, C:C) -> 330 | J2: Frais | K2: =SUMIF(B:B, J2, C:C) -> 0
A3: Loc 10AM 01 | B3: Location entrée | C3: 120 | D3: 2025-05-11 10AM.pdf | E3: 45788 | H3: Vente | I3: =SUMIF(B:B, H3, C:C) -> 0 | J3: Achat Matériel | K3: =SUMIF(B:B, J3, C:C) -> 282.77
A4: Loc 10AM 02 | B4: Location entrée | C4: 120 | D4: 2025-05-18 10AM.pdf | E4: 45795 | H4: Prestation | I4: =SUMIF(B:B, H4, C:C) -> 0 | J4: Location sortie | K4: =SUMIF(B:B, J4, C:C) -> 100
A5: Loc AAW | B5: Location entrée | C5: 90 | D5: 2025-05-17 AAW.pdf | E5: 45796 | H5: Remboursement | I5: =SUMIF(B:B, H5, C:C) -> 0
H6: Don | I6: =SUMIF(B:B, H6, C:C) -> 0
A7: Total Entrées | C7: =SUM(C3:C6) -> 330
A9: Sorties
A10: Prozic - Armoire Elec 1/2 | B10: Achat matériel | C10: 135.38 | D10: 2025-05-07 - Prozic | E10: 45784
A11: Bricoman - Armoire Elec 2/2 + Pinceau | B11: Achat matériel | C11: 96.19 | D11: BRICOMAN.pdf | E11: 45785
A12: Loc AE 10AM 1 | B12: Location sortie | C12: 60 | D12: 2025-05-11 AE SUPAERO.pdf | E12: 45791
A13: Loc AE AAW | B13: Location sortie | C13: 40 | D13: 2025-05-17 AE SUPAERO.pdf | E13: 45791
A14: Prozic - elec AMP 1/2 | B14: Achat matériel | C14: 21.2 | D14: 2025-05-26 Prozic.pdf | E14: 45803
A15: Bricoman - Elec AMP 2/2 | B15: Achat matériel | C15: 30 | D15: 2025-05-26 Bricoman | E15: 45803
A17: Total Sorties | C17: =SUM(C10:C16) -> 382.77

Sheet Avril 2025
A1: Objet | B1: Nature | C1: Montant | D1: Lien Facture | E1: Date | F1: Référence transaction | H1: Bilan
A2: Entrées | H2: Location | I2: =SUMIF(B:B, H2, C:C) -> 0 | J2: Frais | K2: =SUMIF(B:B, J2, C:C) -> 0
A3: Presta AAW | B3: Prestation | C3: 550 | D3: 2025-04-12 AFTER_AFTER_WORK.pdf | E3: 45762 | H3: Vente | I3: =SUMIF(B:B, H3, C:C) -> 0 | J3: Achat Matériel | K3: =SUMIF(B:B, J3, C:C) -> 4.74
H4: Prestation | I4: =SUMIF(B:B, H4, C:C) -> 550 | J4: Location sortie | K4: =SUMIF(B:B, J4, C:C) -> 21
A5: Total Entrées | C5: =SUM(C3:C4) -> 550 | H5: Remboursement | I5: =SUMIF(B:B, H5, C:C) -> 0
H6: Don | I6: =SUMIF(B:B, H6, C:C) -> 0
A7: Sorties
A8: Achats Action | B8: Achat matériel | C8: 4.74 | D8: 2025-04-11 Action.pdf | E8: 45759
A9: Location pratos Audiotec | B9: Location sortie | C9: 21 | D9: 2025-04-14 Audiotec.pdf | E9: 45761
A12: Total Sorties | C12: =SUM(C8:C9) -> 25.74

Sheet Mars 2025
A1: Objet | B1: Nature | C1: Montant | D1: Lien Facture | E1: Date | F1: Référence transaction | H1: Bilan
A2: Entrées | H2: Location | I2: =SUMIF(B:B, H2, C:C) -> 0 | J2: Frais | K2: =SUMIF(B:B, J2, C:C) -> 286.69
A3: Prestation soirée supaero | B3: Prestation | C3: 1390 | D3: 2025-01-11 ACOUSTIC_COLOR.pdf | E3: 45720 | H3: Vente | I3: =SUMIF(B:B, H3, C:C) -> 0 | J3: Achat Matériel | K3: =SUMIF(B:B, J3, C:C) -> 1600
A4: Don Léo Delmas | B4: Don | C4: 100 | E4: 45739 | H4: Prestation | I4: =SUMIF(B:B, H4, C:C) -> 1480 | J4: Location | K4: =SUMIF(B:B, J4, C:C) -> 0
A5: Don Léo Delmas | B5: Don | C5: 30 | E5: 45739 | H5: Remboursement | I5: =SUMIF(B:B, H5, C:C) -> 0
A6: Don Léo Delmas | B6: Don | C6: 10 | E6: 45739 | H6: Don | I6: =SUMIF(B:B, H6, C:C) -> 140
A7: Prestation AAW | B7: Prestation | C7: 90 | D7: 2025-02-22 AFTER_AFTER_WORK.pdf | E7: 45743
A9: Total Entrées | C9: =SUM(C3:C8) -> 1620
A11: Sorties
A12: Paiement Assurance Maif | B12: Frais | C12: =15.83+258.76 -> 274.59 | D12: 2025-03-17 Assurance Maif.pdf | E12: 45731
A13: Frais retard Maif | B13: Frais | C13: 12.1 | D13: 2025-03-17 Frais Maif.pdf | E13: 45731
A14: Achat Midas M32 + Flight | B14: Achat matériel | C14: 1600 | D14: 2025-03-23 MIDAS M32.pdf | E14: 45739
A16: Total Sorties | C16: =SUM(C12:C15) -> 1886.69

Sheet Février 2025
A1: Objet | B1: Nature | C1: Montant | D1: Lien Facture | E1: Date | F1: Référence transaction | H1: Bilan
A2: Entrées | H2: Location | I2: =SUMIF(B:B, H2, C:C) -> 0 | J2: Frais | K2: =SUMIF(B:B, J2, C:C) -> 0
H3: Vente | I3: =SUMIF(B:B, H3, C:C) -> 0 | J3: Achat Matériel | K3: =SUMIF(B:B, J3, C:C) -> 0
A4: Total Entrées | C4: =SUM(C3) -> 0 | H4: Prestation | I4: =SUMIF(B:B, H4, C:C) -> 0 | J4: Location | K4: =SUMIF(B:B, J4, C:C) -> 0
H5: Remboursement | I5: =SUMIF(B:B, H5, C:C) -> 0
A6: Sorties | H6: Don | I6: =SUMIF(B:B, H6, C:C) -> 0
A8: Total Sorties | C8: =SUM(C7) -> 0

Sheet Janvier 2025
A1: Objet | B1: Nature | C1: Montant | D1: Lien Facture | E1: Date facture | F1: Référence transaction | H1: Bilan
A2: Entrées | H2: Location | I2: =SUMIF(B:B, H2, C:C) -> 0 | J2: Frais | K2: =SUMIF(B:B, J2, C:C) -> 0
A3: Haut Parleur Yamaha DXR15 | B3: Vente | C3: 249 | D3: 2024-01-21 Haut Parleur Alumnis.pdf | E3: 45678 | H3: Vente | I3: =SUMIF(B:B, H3, C:C) -> 249 | J3: Achat Matériel | K3: =SUMIF(B:B, J3, C:C) -> 203.4
H4: Prestation | I4: =SUMIF(B:B, H4, C:C) -> 0 | J4: Location | K4: =SUMIF(B:B, J4, C:C) -> 0
H5: Remboursement | I5: =SUMIF(B:B, H5, C:C) -> 0
A6: Total Entrées | C6: =SUM(C3:C5) -> 249 | H6: Don | I6: =SUMIF(B:B, H6, C:C) -> 0
A8: Sorties
A9: Haut-parleur Yamaha DXR15 | B9: Achat matériel | C9: 203.4 | D9: 2025-01-15 Audio system.pdf | E9: 45664
A11: Total Sorties | C11: =SUM(C9:C10) -> 203.4

Sheet Dec2024
A1: Objet | B1: Nature | C1: Montant | D1: Lien Facture | E1: Date | F1: Référence transaction | H1: Bilan
A2: Entrées | H2: Location | I2: =SUMIF(B:B, H2, C:C) -> 0 | J2: Frais | K2: =SUMIF(B:B, J2, C:C) -> 0
H3: Vente | I3: =SUMIF(B:B, H3, C:C) -> 0 | J3: Achat Matériel | K3: =SUMIF(B:B, J3, C:C) -> 295
A4: Total Entrées | C4: =SUM(C3) -> 0 | H4: Prestation | I4: =SUMIF(B:B, H4, C:C) -> 0 | J4: Location | K4: =SUMIF(B:B, J4, C:C) -> 0
H5: Remboursement | I5: =SUMIF(B:B, H5, C:C) -> 0
A6: Sorties | H6: Don | I6: =SUMIF(B:B, H6, C:C) -> 0
A7: Achat x10 clamps pliables Acoustic Color | B7: Achat Matériel | C7: 160 | D7: 2024-12-11 Acoustic Color.pdf | E7: 45637
A8: Flight case 2 eyes Thomann | B8: Achat Matériel | C8: 135 | D8: 2024-12-20 Thomann.png | E8: 45646
A9: Total Sorties | C9: =SUM(C7:C8) -> 295

Sheet Nov2024
A1: Objet | B1: Nature | C1: Montant | D1: Lien Facture | E1: Date | F1: Référence transaction | H1: Bilan
A2: Entrées | H2: Location | I2: 0 | J2: Frais | K2: =SUMIF(B:B, J2, C:C) -> 155.34
A3: Prestation lumière GALA ISAE 2024 | B3: Prestation | C3: 9200 | D3: 05-11-24 Gala Isae Supaero.pdf | E3: 45601 | H3: Vente | I3: =SUMIF(B:B, H3, C:C) -> 0 | J3: Achat Matériel | K3: =SUMIF(B:B, J3, C:C) -> 8417.51
A4: Remboursement frais cartes | B4: Remboursement | C4: 28.01 | E4: 45601 | H4: Prestation | I4: =SUMIF(B:B, H4, C:C) -> 9200 | J4: Location | K4: =SUMIF(B:B, J4, C:C) -> 48.15
A5: Total Entrées | C5: =SUM(C3:C4) -> 9228.01 | H5: Remboursement | I5: =SUMIF(B:B, H5, C:C) -> 28.01
H6: Don | I6: =SUMIF(B:B, H6, C:C) -> 0
A7: Sorties
A8: Frais carte gold | B8: Frais | C8: 20.81 | E8: 45601
A9: Frais expédition carte | B9: Frais | C9: 7.2 | E9: 45601
A10: Achat lumières SHEHDS | B10: Achat Matériel | C10: 6366.4 | D10: 2024-11-05 Shehds.pdf | E10: 45601
A11: Frais paiement international qonto | B11: Frais | C11: 127.33 | D11: A RENSEIGNER | E11: 45602
A12: Achats tapis aliexpress | B12: Achat Matériel | C12: 142.59 | D12: 05-11-24 Aliexpress.pdf | E12: 45601
A13: Achat peinture dorée | B13: Achat Matériel | C13: 10.47 | D13: 05-11-24 Cultura.pdf | E13: 45601
A14: Achat x2 FOS Tornado AC | B14: Achat Matériel | C14: 1140 | D14: 2024-11-10 Acoustic Color.pdf | E14: 45605
A15: Achat Thomann | B15: Achat Matériel | C15: 341.4 | D15: 2024-11-10 Thomann.pdf | E15: 45606
A16: Achat Boitier HDMI-RJ45 Amazon | B16: Achat Matériel | C16: 47.99 | D16: 2024-11-10 Amazon.pdf | E16: 45606
A17: Achat x4 clamps pliables Sono Matériel | B17: Achat Matériel | C17: 66 | D17: 2024-11-15 Sono Materiel.pdf | E17: 45611
A18: Achat extension Sunlite | B18: Achat Matériel | C18: 225.34 | D18: 2024-11-17 DMXSoft.pdf | E18: 45613
A19: Achat élingues Bax shop | B19: Achat Matériel | C19: 77.32 | D19: 2024-11-17 Bax shop.pdf | E19: 45613
A20: Location Resolume | B20: Location | C20: 48.15 | D20: 2024-11-27 Gearbooker.pdf | E20: 45623
A22: Total Sorties | C22: =SUM(C8:C21) -> 8621

Sheet Oct2024
A1: Objet | B1: Nature | C1: Montant | D1: Lien Facture | E1: Date | F1: Référence transaction | H1: Bilan
A2: Entrées | H2: Location | I2: =SUMIF(B:B, H2, C:C) -> 0 | J2: Frais | K2: =SUMIF(B:B, J2, C:C) -> 0
H3: Vente | I3: =SUMIF(B:B, H3, C:C) -> 0 | J3: Achat Matériel | K3: =SUMIF(B:B, J3, C:C) -> 0
A4: Total Entrées | C4: =SUM(C3) -> 0 | H4: Prestation | I4: =SUMIF(B:B, H4, C:C) -> 0 | J4: Location | K4: =SUMIF(B:B, J4, C:C) -> 0
H5: Remboursement | I5: =SUMIF(B:B, H5, C:C) -> 0
A6: Sorties | H6: Don | I6: =SUMIF(B:B, H6, C:C) -> 0
A8: Total Sorties | C8: =SUM(C7) -> 0

Sheet Sept2024
A1: Objet | B1: Nature | C1: Montant | D1: Lien Facture | E1: Date | F1: Référence transaction | H1: Bilan
A2: Entrées | H2: Location | I2: =SUMIF(B:B, H2, C:C) -> 0 | J2: Frais | K2: =SUMIF(B:B, J2, C:C) -> 125.28
A3: Don Léo Delmas | B3: Don | C3: 101 | E3: 45551 | H3: Vente | I3: =SUMIF(B:B, H3, C:C) -> 0 | J3: Achat Matériel | K3: =SUMIF(B:B, J3, C:C) -> 0
A4: Total Entrées | C4: =SUM(C3) -> 101 | H4: Prestation | I4: =SUMIF(B:B, H4, C:C) -> 0 | J4: Location | K4: =SUMIF(B:B, J4, C:C) -> 0
H5: Remboursement | I5: =SUMIF(B:B, H5, C:C) -> 0
A6: Sorties | H6: Don | I6: =SUMIF(B:B, H6, C:C) -> 101
A7: Abonnement annuel | B7: Frais | C7: 125.28 | D7: 16-09-24 Qonto.pdf | E7: 45551
A8: Total Sorties | C8: =SUM(C7) -> 125.28

Sheet Aout2024
A1: Objet | B1: Nature | C1: Montant | D1: Lien Facture | E1: Date | F1: Référence transaction | H1: Bilan
A2: Entrées | H2: Location | I2: =SUMIF(B:B, H2, C:C) -> 0 | J2: Frais | K2: =SUMIF(B:B, J2, C:C) -> 41.67
A3: Prestation Laser GALA ISAE 2024 | B3: Prestation | C3: 4650 | D3: Fac01 | E3: 45518 | H3: Vente | I3: =SUMIF(B:B, H3, C:C) -> 0 | J3: Achat Matériel | K3: =SUMIF(B:B, J3, C:C) -> 4583.22
A4: Total Entrées | C4: =SUM(C3) -> 4650 | H4: Prestation | I4: =SUMIF(B:B, H4, C:C) -> 4650 | J4: Location | K4: =SUMIF(B:B, J4, C:C) -> 0
H5: Remboursement | I5: =SUMIF(B:B, H5, C:C) -> 0
A6: Sorties | H6: Don | I6: =SUMIF(B:B, H6, C:C) -> 0
A7: Achat 4 Lasers 10W + acc | B7: Achat Matériel | C7: 4583.22 | D7: Facture4PI | E7: 45518
A8: Frais virement international qonto | B8: Frais | C8: 41.67 | D8: 14-08-24 Qonto.pdf
A9: Total Sorties | C9: =SUM(C7:C8) -> 4624.89
